Workbook

Sheet EVERYTHING (Skaters)
K1: Quick Jumps: | M1: Goalies | N1: Plus/Minus & PP
M2: PIM/Hits/BS | N2: Help & Info
H3: AAV, Salary, or Cap Hit? (Type it): | M3: Potential | N3: EVERYTHING
H4: AAV | M4: ='Points&Potential'!$M$4 -> Updated: Aug 02 | P4: *Age is as of Jul 22
A6: Rank | B6: Player | C6: Age | D6: Pos | E6: 3YP | F6: Upside | G6: Team | H6: Games | I6: Goals | J6: Assists | K6: Points | L6: +/- | M6: PP Unit | N6: PIM | O6: Hits | P6: BLKS | Q6: SOG | R6: Sleeper | S6: =IF(H4="2011 - 2012 Cap #","Cap Hit", "Salary") -> Salary | T6: Band-Aid Boy | U6: Notes | V6: Rookie
A7: 1 | B7: Connor McDavid | C7: =VLOOKUP(B7, Paste!$AG$3:$AH$2083, 2, FALSE) -> 29.4 | D7: =VLOOKUP($B7, Paste!$A$3:$H$933, 6, FALSE) -> C | E7: =IFERROR(VLOOKUP($B7, Paste!$J$3:$L$933, 3, FALSE), "") -> 135 | F7: =IFERROR(VLOOKUP($B7, Paste!$J$3:$L$933, 2, FALSE), "") -> 160 | G7: =VLOOKUP($B7, Paste!$A$3:$H$933, 8, FALSE) -> EDM | H7: =VLOOKUP($B7, Paste!$A$3:$H$933, 2, FALSE) -> 77 | I7: =VLOOKUP($B7, Paste!$A$3:$H$933, 3, FALSE) -> 36.462054 | J7: =K7-I7 -> 94.720676 | K7: =VLOOKUP($B7, Paste!$A$3:$H$933, 4, FALSE) -> 131.18273 | L7: =IF(ISBLANK(VLOOKUP(B7, 'SOG&PlusMinus'!$B$7:$E$912, 3, FALSE)), "", VLOOKUP(B7,'SOG&PlusMinus'!$B$7:$E$912, 3, FALSE)) -> A | M7: =IF(ISBLANK(VLOOKUP(B7, 'SOG&PlusMinus'!$B$7:$E$912, 4, FALSE)), "", VLOOKUP(B7, 'SOG&PlusMinus'!$B$7:$E$912, 4, FALSE)) -> 1 | N7: =VLOOKUP($B7, Paste!$A$3:$H$933, 5, FALSE) -> 37.986667 | O7: =IF(ISERROR(VLOOKUP(B7, Paste!$AB$3:$AE$2349, 3, FALSE)), "", VLOOKUP(B7, Paste!$AB$3:$AE$2349, 3, FALSE)) -> 42 | P7: =IF(ISERROR(VLOOKUP(B7, Paste!$AB$3:$AC$2343, 2, FALSE)), "", VLOOKUP(B7, Paste!$AB$3:$AC$2343, 2, FALSE)) -> 27 | Q7: =IF(ISERROR(VLOOKUP(B7, Paste!$AB$3:$AE$2349, 4, FALSE)), "", VLOOKUP(B7, Paste!$AB$3:$AE$2349, 4, FALSE)) -> 277 | R7: =IF(ISERROR(VLOOKUP(B7, Paste!$N$3:$N$250, 1, FALSE)), "", VLOOKUP(B7, Paste!$N$3:$O$250, 2, FALSE)) | S7: =VLOOKUP($B7, Paste!$W$3:$Z$10064, IF($H$4="Cap Hit",3, IF($H$4="AAV", 4, 2)), FALSE) -> 12.5 | T7: =IF(ISERROR(VLOOKUP(B7, Paste!$Q$3:$Q$245, 1, FALSE)), "", VLOOKUP(B7, Paste!$Q$3:$R$245, 2, FALSE)) | U7: =IF(VLOOKUP(B7, 'Points&Potential'!$B$7:$O$943, 14, FALSE)=0, "", VLOOKUP(B7, 'Points&Potential'!$B$7:$O$943, 14, FALSE)) | V7: =IF(ISERROR(VLOOKUP(B7, Paste!$T$3:$T$1045, 1, FALSE)), "", VLOOKUP(B7, Paste!$T$3:$U$1144, 2, FALSE))
A8: 2 | B8: Nikita Kucherov | C8: =VLOOKUP(B8, Paste!$AG$3:$AH$2083, 2, FALSE) -> 33 | D8: =VLOOKUP($B8, Paste!$A$3:$H$933, 6, FALSE) -> RW | E8: =IFERROR(VLOOKUP($B8, Paste!$J$3:$L$933, 3, FALSE), "") -> 120 | F8: =IFERROR(VLOOKUP($B8, Paste!$J$3:$L$933, 2, FALSE), "") -> 140 | G8: =VLOOKUP($B8, Paste!$A$3:$H$933, 8, FALSE) -> TBL | H8: =VLOOKUP($B8, Paste!$A$3:$H$933, 2, FALSE) -> 80.666667 | I8: =VLOOKUP($B8, Paste!$A$3:$H$933, 3, FALSE) -> 41.575334 | J8: =K8-I8 -> 86.455976 | K8: =VLOOKUP($B8, Paste!$A$3:$H$933, 4, FALSE) -> 128.03131 | L8: =IF(ISBLANK(VLOOKUP(B8, 'SOG&PlusMinus'!$B$7:$E$912, 3, FALSE)), "", VLOOKUP(B8,'SOG&PlusMinus'!$B$7:$E$912, 3, FALSE)) -> A | M8: =IF(ISBLANK(VLOOKUP(B8, 'SOG&PlusMinus'!$B$7:$E$912, 4, FALSE)), "", VLOOKUP(B8, 'SOG&PlusMinus'!$B$7:$E$912, 4, FALSE)) -> 1 | N8: =VLOOKUP($B8, Paste!$A$3:$H$933, 5, FALSE) -> 39.991525 | O8: =IF(ISERROR(VLOOKUP(B8, Paste!$AB$3:$AE$2349, 3, FALSE)), "", VLOOKUP(B8, Paste!$AB$3:$AE$2349, 3, FALSE)) -> 35 | P8: =IF(ISERROR(VLOOKUP(B8, Paste!$AB$3:$AC$2343, 2, FALSE)), "", VLOOKUP(B8, Paste!$AB$3:$AC$2343, 2, FALSE)) -> 32 | Q8: =IF(ISERROR(VLOOKUP(B8, Paste!$AB$3:$AE$2349, 4, FALSE)), "", VLOOKUP(B8, Paste!$AB$3:$AE$2349, 4, FALSE)) -> 258 | R8: =IF(ISERROR(VLOOKUP(B8, Paste!$N$3:$N$250, 1, FALSE)), "", VLOOKUP(B8, Paste!$N$3:$O$250, 2, FALSE)) | S8: =VLOOKUP($B8, Paste!$W$3:$Z$10064, IF($H$4="Cap Hit",3, IF($H$4="AAV", 4, 2)), FALSE) -> 9.5 | T8: =IF(ISERROR(VLOOKUP(B8, Paste!$Q$3:$Q$245, 1, FALSE)), "", VLOOKUP(B8, Paste!$Q$3:$R$245, 2, FALSE)) | U8: =IF(VLOOKUP(B8, 'Points&Potential'!$B$7:$O$943, 14, FALSE)=0, "", VLOOKUP(B8, 'Points&Potential'!$B$7:$O$943, 14, FALSE)) | V8: =IF(ISERROR(VLOOKUP(B8, Paste!$T$3:$T$1045, 1, FALSE)), "", VLOOKUP(B8, Paste!$T$3:$U$1144, 2, FALSE))
A9: 3 | B9: Nathan MacKinnon | C9: =VLOOKUP(B9, Paste!$AG$3:$AH$2083, 2, FALSE) -> 30.8 | D9: =VLOOKUP($B9, Paste!$A$3:$H$933, 6, FALSE) -> C | E9: =IFERROR(VLOOKUP($B9, Paste!$J$3:$L$933, 3, FALSE), "") -> 123 | F9: =IFERROR(VLOOKUP($B9, Paste!$J$3:$L$933, 2, FALSE), "") -> 145 | G9: =VLOOKUP($B9, Paste!$A$3:$H$933, 8, FALSE) -> COL | H9: =VLOOKUP($B9, Paste!$A$3:$H$933, 2, FALSE) -> 82.333333 | I9: =VLOOKUP($B9, Paste!$A$3:$H$933, 3, FALSE) -> 45.150263 | J9: =K9-I9 -> 81.06191 | K9: =VLOOKUP($B9, Paste!$A$3:$H$933, 4, FALSE) -> 126.21217 | L9: =IF(ISBLANK(VLOOKUP(B9, 'SOG&PlusMinus'!$B$7:$E$912, 3, FALSE)), "", VLOOKUP(B9,'SOG&PlusMinus'!$B$7:$E$912, 3, FALSE)) -> A | M9: =IF(ISBLANK(VLOOKUP(B9, 'SOG&PlusMinus'!$B$7:$E$912, 4, FALSE)), "", VLOOKUP(B9, 'SOG&PlusMinus'!$B$7:$E$912, 4, FALSE)) -> 1 | N9: =VLOOKUP($B9, Paste!$A$3:$H$933, 5, FALSE) -> 41.679115 | O9: =IF(ISERROR(VLOOKUP(B9, Paste!$AB$3:$AE$2349, 3, FALSE)), "", VLOOKUP(B9, Paste!$AB$3:$AE$2349, 3, FALSE)) -> 54 | P9: =IF(ISERROR(VLOOKUP(B9, Paste!$AB$3:$AC$2343, 2, FALSE)), "", VLOOKUP(B9, Paste!$AB$3:$AC$2343, 2, FALSE)) -> 56 | Q9: =IF(ISERROR(VLOOKUP(B9, Paste!$AB$3:$AE$2349, 4, FALSE)), "", VLOOKUP(B9, Paste!$AB$3:$AE$2349, 4, FALSE)) -> 354 | R9: =IF(ISERROR(VLOOKUP(B9, Paste!$N$3:$N$250, 1, FALSE)), "", VLOOKUP(B9, Paste!$N$3:$O$250, 2, FALSE)) | S9: =VLOOKUP($B9, Paste!$W$3:$Z$10064, IF($H$4="Cap Hit",3, IF($H$4="AAV", 4, 2)), FALSE) -> 12.6 | T9: =IF(ISERROR(VLOOKUP(B9, Paste!$Q$3:$Q$245, 1, FALSE)), "", VLOOKUP(B9, Paste!$Q$3:$R$245, 2, FALSE)) | U9: =IF(VLOOKUP(B9, 'Points&Potential'!$B$7:$O$943, 14, FALSE)=0, "", VLOOKUP(B9, 'Points&Potential'!$B$7:$O$943, 14, FALSE)) | V9: =IF(ISERROR(VLOOKUP(B9, Paste!$T$3:$T$1045, 1, FALSE)), "", VLOOKUP(B9, Paste!$T$3:$U$1144, 2, FALSE))
A10: 4 | B10: Macklin Celebrini | C10: =VLOOKUP(B10, Paste!$AG$3:$AH$2083, 2, FALSE) -> 20 | D10: =VLOOKUP($B10, Paste!$A$3:$H$933, 6, FALSE) -> C | E10: =IFERROR(VLOOKUP($B10, Paste!$J$3:$L$933, 3, FALSE), "") -> 112 | F10: =IFERROR(VLOOKUP($B10, Paste!$J$3:$L$933, 2, FALSE), "") -> 125 | G10: =VLOOKUP($B10, Paste!$A$3:$H$933, 8, FALSE) -> SJS | H10: =VLOOKUP($B10, Paste!$A$3:$H$933, 2, FALSE) -> 78 | I10: =VLOOKUP($B10, Paste!$A$3:$H$933, 3, FALSE) -> 39 | J10: =K10-I10 -> 72.815418 | K10: =VLOOKUP($B10, Paste!$A$3:$H$933, 4, FALSE) -> 111.81542 | L10: =IF(ISBLANK(VLOOKUP(B10, 'SOG&PlusMinus'!$B$7:$E$912, 3, FALSE)), "", VLOOKUP(B10,'SOG&PlusMinus'!$B$7:$E$912, 3, FALSE)) -> B | M10: =IF(ISBLANK(VLOOKUP(B10, 'SOG&PlusMinus'!$B$7:$E$912, 4, FALSE)), "", VLOOKUP(B10, 'SOG&PlusMinus'!$B$7:$E$912, 4, FALSE)) -> 1 | N10: =VLOOKUP($B10, Paste!$A$3:$H$933, 5, FALSE) -> 35.1 | O10: =IF(ISERROR(VLOOKUP(B10, Paste!$AB$3:$AE$2349, 3, FALSE)), "", VLOOKUP(B10, Paste!$AB$3:$AE$2349, 3, FALSE)) -> 55 | P10: =IF(ISERROR(VLOOKUP(B10, Paste!$AB$3:$AC$2343, 2, FALSE)), "", VLOOKUP(B10, Paste!$AB$3:$AC$2343, 2, FALSE)) -> 55 | Q10: =IF(ISERROR(VLOOKUP(B10, Paste!$AB$3:$AE$2349, 4, FALSE)), "", VLOOKUP(B10, Paste!$AB$3:$AE$2349, 4, FALSE)) -> 281 | R10: =IF(ISERROR(VLOOKUP(B10, Paste!$N$3:$N$250, 1, FALSE)), "", VLOOKUP(B10, Paste!$N$3:$O$250, 2, FALSE)) | S10: =VLOOKUP($B10, Paste!$W$3:$Z$10064, IF($H$4="Cap Hit",3, IF($H$4="AAV", 4, 2)), FALSE) -> 4.475 | T10: =IF(ISERROR(VLOOKUP(B10, Paste!$Q$3:$Q$245, 1, FALSE)), "", VLOOKUP(B10, Paste!$Q$3:$R$245, 2, FALSE)) | U10: =IF(VLOOKUP(B10, 'Points&Potential'!$B$7:$O$943, 14, FALSE)=0, "", VLOOKUP(B10, 'Points&Potential'!$B$7:$O$943, 14, FALSE)) | V10: =IF(ISERROR(VLOOKUP(B10, Paste!$T$3:$T$1045, 1, FALSE)), "", VLOOKUP(B10, Paste!$T$3:$U$1144, 2, FALSE))
A11: 5 | B11: Jason Robertson | C11: =VLOOKUP(B11, Paste!$AG$3:$AH$2083, 2, FALSE) -> 26.9 | D11: =VLOOKUP($B11, Paste!$A$3:$H$933, 6, FALSE) -> LW | E11: =IFERROR(VLOOKUP($B11, Paste!$J$3:$L$933, 3, FALSE), "") -> 93 | F11: =IFERROR(VLOOKUP($B11, Paste!$J$3:$L$933, 2, FALSE), "") -> 110 | G11: =VLOOKUP($B11, Paste!$A$3:$H$933, 8, FALSE) -> DAL | H11: =VLOOKUP($B11, Paste!$A$3:$H$933, 2, FALSE) -> 84 | I11: =VLOOKUP($B11, Paste!$A$3:$H$933, 3, FALSE) -> 38.79345 | J11: =K11-I11 -> 70.478485 | K11: =VLOOKUP($B11, Paste!$A$3:$H$933, 4, FALSE) -> 109.27194 | L11: =IF(ISBLANK(VLOOKUP(B11, 'SOG&PlusMinus'!$B$7:$E$912, 3, FALSE)), "", VLOOKUP(B11,'SOG&PlusMinus'!$B$7:$E$912, 3, FALSE)) -> A | M11: =IF(ISBLANK(VLOOKUP(B11, 'SOG&PlusMinus'!$B$7:$E$912, 4, FALSE)), "", VLOOKUP(B11, 'SOG&PlusMinus'!$B$7:$E$912, 4, FALSE)) -> 1 | N11: =VLOOKUP($B11, Paste!$A$3:$H$933, 5, FALSE) -> 24.585366 | O11: =IF(ISERROR(VLOOKUP(B11, Paste!$AB$3:$AE$2349, 3, FALSE)), "", VLOOKUP(B11, Paste!$AB$3:$AE$2349, 3, FALSE)) -> 59 | P11: =IF(ISERROR(VLOOKUP(B11, Paste!$AB$3:$AC$2343, 2, FALSE)), "", VLOOKUP(B11, Paste!$AB$3:$AC$2343, 2, FALSE)) -> 34 | Q11: =IF(ISERROR(VLOOKUP(B11, Paste!$AB$3:$AE$2349, 4, FALSE)), "", VLOOKUP(B11, Paste!$AB$3:$AE$2349, 4, FALSE)) -> 286 | R11: =IF(ISERROR(VLOOKUP(B11, Paste!$N$3:$N$250, 1, FALSE)), "", VLOOKUP(B11, Paste!$N$3:$O$250, 2, FALSE)) | S11: =VLOOKUP($B11, Paste!$W$3:$Z$10064, IF($H$4="Cap Hit",3, IF($H$4="AAV", 4, 2)), FALSE) -> 12 | T11: =IF(ISERROR(VLOOKUP(B11, Paste!$Q$3:$Q$245, 1, FALSE)), "", VLOOKUP(B11, Paste!$Q$3:$R$245, 2, FALSE)) | U11: =IF(VLOOKUP(B11, 'Points&Potential'!$B$7:$O$943, 14, FALSE)=0, "", VLOOKUP(B11, 'Points&Potential'!$B$7:$O$943, 14, FALSE)) | V11: =IF(ISERROR(VLOOKUP(B11, Paste!$T$3:$T$1045, 1, FALSE)), "", VLOOKUP(B11, Paste!$T$3:$U$1144, 2, FALSE))
A12: 6 | B12: Martin Necas | C12: =VLOOKUP(B12, Paste!$AG$3:$AH$2083, 2, FALSE) -> 27.4 | D12: =VLOOKUP($B12, Paste!$A$3:$H$933, 6, FALSE) -> RW | E12: =IFERROR(VLOOKUP($B12, Paste!$J$3:$L$933, 3, FALSE), "") -> 105 | F12: =IFERROR(VLOOKUP($B12, Paste!$J$3:$L$933, 2, FALSE), "") -> 112 | G12: =VLOOKUP($B12, Paste!$A$3:$H$933, 8, FALSE) -> COL | H12: =VLOOKUP($B12, Paste!$A$3:$H$933, 2, FALSE) -> 80 | I12: =VLOOKUP($B12, Paste!$A$3:$H$933, 3, FALSE) -> 32 | J12: =K12-I12 -> 75.804813 | K12: =VLOOKUP($B12, Paste!$A$3:$H$933, 4, FALSE) -> 107.80481 | L12: =IF(ISBLANK(VLOOKUP(B12, 'SOG&PlusMinus'!$B$7:$E$912, 3, FALSE)), "", VLOOKUP(B12,'SOG&PlusMinus'!$B$7:$E$912, 3, FALSE)) -> A | M12: =IF(ISBLANK(VLOOKUP(B12, 'SOG&PlusMinus'!$B$7:$E$912, 4, FALSE)), "", VLOOKUP(B12, 'SOG&PlusMinus'!$B$7:$E$912, 4, FALSE)) -> 1 | N12: =VLOOKUP($B12, Paste!$A$3:$H$933, 5, FALSE) -> 30.08547 | O12: =IF(ISERROR(VLOOKUP(B12, Paste!$AB$3:$AE$2349, 3, FALSE)), "", VLOOKUP(B12, Paste!$AB$3:$AE$2349, 3, FALSE)) -> 76 | P12: =IF(ISERROR(VLOOKUP(B12, Paste!$AB$3:$AC$2343, 2, FALSE)), "", VLOOKUP(B12, Paste!$AB$3:$AC$2343, 2, FALSE)) -> 26 | Q12: =IF(ISERROR(VLOOKUP(B12, Paste!$AB$3:$AE$2349, 4, FALSE)), "", VLOOKUP(B12, Paste!$AB$3:$AE$2349, 4, FALSE)) -> 216 | R12: =IF(ISERROR(VLOOKUP(B12, Paste!$N$3:$N$250, 1, FALSE)), "", VLOOKUP(B12, Paste!$N$3:$O$250, 2, FALSE)) | S12: =VLOOKUP($B12, Paste!$W$3:$Z$10064, IF($H$4="Cap Hit",3, IF($H$4="AAV", 4, 2)), FALSE) -> 11.5 | T12: =IF(ISERROR(VLOOKUP(B12, Paste!$Q$3:$Q$245, 1, FALSE)), "", VLOOKUP(B12, Paste!$Q$3:$R$245, 2, FALSE)) | U12: =IF(VLOOKUP(B12, 'Points&Potential'!$B$7:$O$943, 14, FALSE)=0, "", VLOOKUP(B12, 'Points&Potential'!$B$7:$O$943, 14, FALSE)) | V12: =IF(ISERROR(VLOOKUP(B12, Paste!$T$3:$T$1045, 1, FALSE)), "", VLOOKUP(B12, Paste!$T$3:$U$1144, 2, FALSE))
A13: 7 | B13: Leon Draisaitl | C13: =VLOOKUP(B13, Paste!$AG$3:$AH$2083, 2, FALSE) -> 30.6 | D13: =VLOOKUP($B13, Paste!$A$3:$H$933, 6, FALSE) -> C | E13: =IFERROR(VLOOKUP($B13, Paste!$J$3:$L$933, 3, FALSE), "") -> 112 | F13: =IFERROR(VLOOKUP($B13, Paste!$J$3:$L$933, 2, FALSE), "") -> 145 | G13: =VLOOKUP($B13, Paste!$A$3:$H$933, 8, FALSE) -> EDM | H13: =VLOOKUP($B13, Paste!$A$3:$H$933, 2, FALSE) -> 74.333333 | I13: =VLOOKUP($B13, Paste!$A$3:$H$933, 3, FALSE) -> 44.196876 | J13: =K13-I13 -> 61.778262 | K13: =VLOOKUP($B13, Paste!$A$3:$H$933, 4, FALSE) -> 105.97514 | L13: =IF(ISBLANK(VLOOKUP(B13, 'SOG&PlusMinus'!$B$7:$E$912, 3, FALSE)), "", VLOOKUP(B13,'SOG&PlusMinus'!$B$7:$E$912, 3, FALSE)) -> A | M13: =IF(ISBLANK(VLOOKUP(B13, 'SOG&PlusMinus'!$B$7:$E$912, 4, FALSE)), "", VLOOKUP(B13, 'SOG&PlusMinus'!$B$7:$E$912, 4, FALSE)) -> 1 | N13: =VLOOKUP($B13, Paste!$A$3:$H$933, 5, FALSE) -> 46.58679 | O13: =IF(ISERROR(VLOOKUP(B13, Paste!$AB$3:$AE$2349, 3, FALSE)), "", VLOOKUP(B13, Paste!$AB$3:$AE$2349, 3, FALSE)) -> 37 | P13: =IF(ISERROR(VLOOKUP(B13, Paste!$AB$3:$AC$2343, 2, FALSE)), "", VLOOKUP(B13, Paste!$AB$3:$AC$2343, 2, FALSE)) -> 22 | Q13: =IF(ISERROR(VLOOKUP(B13, Paste!$AB$3:$AE$2349, 4, FALSE)), "", VLOOKUP(B13, Paste!$AB$3:$AE$2349, 4, FALSE)) -> 223 | R13: =IF(ISERROR(VLOOKUP(B13, Paste!$N$3:$N$250, 1, FALSE)), "", VLOOKUP(B13, Paste!$N$3:$O$250, 2, FALSE)) | S13: =VLOOKUP($B13, Paste!$W$3:$Z$10064, IF($H$4="Cap Hit",3, IF($H$4="AAV", 4, 2)), FALSE) -> 14 | T13: =IF(ISERROR(VLOOKUP(B13, Paste!$Q$3:$Q$245, 1, FALSE)), "", VLOOKUP(B13, Paste!$Q$3:$R$245, 2, FALSE)) -> Y | U13: =IF(VLOOKUP(B13, 'Points&Potential'!$B$7:$O$943, 14, FALSE)=0, "", VLOOKUP(B13, 'Points&Potential'!$B$7:$O$943, 14, FALSE)) | V13: =IF(ISERROR(VLOOKUP(B13, Paste!$T$3:$T$1045, 1, FALSE)), "", VLOOKUP(B13, Paste!$T$3:$U$1144, 2, FALSE))
A14: 8 | B14: David Pastrnak | C14: =VLOOKUP(B14, Paste!$AG$3:$AH$2083, 2, FALSE) -> 30.1 | D14: =VLOOKUP($B14, Paste!$A$3:$H$933, 6, FALSE) -> RW | E14: =IFERROR(VLOOKUP($B14, Paste!$J$3:$L$933, 3, FALSE), "") -> 100 | F14: =IFERROR(VLOOKUP($B14, Paste!$J$3:$L$933, 2, FALSE), "") -> 115 | G14: =VLOOKUP($B14, Paste!$A$3:$H$933, 8, FALSE) -> BOS | H14: =VLOOKUP($B14, Paste!$A$3:$H$933, 2, FALSE) -> 82.333333 | I14: =VLOOKUP($B14, Paste!$A$3:$H$933, 3, FALSE) -> 38.152501 | J14: =K14-I14 -> 67.214735 | K14: =VLOOKUP($B14, Paste!$A$3:$H$933, 4, FALSE) -> 105.36724 | L14: =IF(ISBLANK(VLOOKUP(B14, 'SOG&PlusMinus'!$B$7:$E$912, 3, FALSE)), "", VLOOKUP(B14,'SOG&PlusMinus'!$B$7:$E$912, 3, FALSE)) -> B | M14: =IF(ISBLANK(VLOOKUP(B14, 'SOG&PlusMinus'!$B$7:$E$912, 4, FALSE)), "", VLOOKUP(B14, 'SOG&PlusMinus'!$B$7:$E$912, 4, FALSE)) -> 1 | N14: =VLOOKUP($B14, Paste!$A$3:$H$933, 5, FALSE) -> 55.002766 | O14: =IF(ISERROR(VLOOKUP(B14, Paste!$AB$3:$AE$2349, 3, FALSE)), "", VLOOKUP(B14, Paste!$AB$3:$AE$2349, 3, FALSE)) -> 73 | P14: =IF(ISERROR(VLOOKUP(B14, Paste!$AB$3:$AC$2343, 2, FALSE)), "", VLOOKUP(B14, Paste!$AB$3:$AC$2343, 2, FALSE)) -> 26 | Q14: =IF(ISERROR(VLOOKUP(B14, Paste!$AB$3:$AE$2349, 4, FALSE)), "", VLOOKUP(B14, Paste!$AB$3:$AE$2349, 4, FALSE)) -> 296 | R14: =IF(ISERROR(VLOOKUP(B14, Paste!$N$3:$N$250, 1, FALSE)), "", VLOOKUP(B14, Paste!$N$3:$O$250, 2, FALSE)) | S14: =VLOOKUP($B14, Paste!$W$3:$Z$10064, IF($H$4="Cap Hit",3, IF($H$4="AAV", 4, 2)), FALSE) -> 11.25 | T14: =IF(ISERROR(VLOOKUP(B14, Paste!$Q$3:$Q$245, 1, FALSE)), "", VLOOKUP(B14, Paste!$Q$3:$R$245, 2, FALSE)) | U14: =IF(VLOOKUP(B14, 'Points&Potential'!$B$7:$O$943, 14, FALSE)=0, "", VLOOKUP(B14, 'Points&Potential'!$B$7:$O$943, 14, FALSE)) | V14: =IF(ISERROR(VLOOKUP(B14, Paste!$T$3:$T$1045, 1, FALSE)), "", VLOOKUP(B14, Paste!$T$3:$U$1144, 2, FALSE))
A15: 9 | B15: Mitch Marner | C15: =VLOOKUP(B15, Paste!$AG$3:$AH$2083, 2, FALSE) -> 29.1 | D15: =VLOOKUP($B15, Paste!$A$3:$H$933, 6, FALSE) -> RW | E15: =IFERROR(VLOOKUP($B15, Paste!$J$3:$L$933, 3, FALSE), "") -> 98 | F15: =IFERROR(VLOOKUP($B15, Paste!$J$3:$L$933, 2, FALSE), "") -> 118 | G15: =VLOOKUP($B15, Paste!$A$3:$H$933, 8, FALSE) -> VGK | H15: =VLOOKUP($B15, Paste!$A$3:$H$933, 2, FALSE) -> 83 | I15: =VLOOKUP($B15, Paste!$A$3:$H$933, 3, FALSE) -> 27.235265 | J15: =K15-I15 -> 71.736269 | K15: =VLOOKUP($B15, Paste!$A$3:$H$933, 4, FALSE) -> 98.971534 | L15: =IF(ISBLANK(VLOOKUP(B15, 'SOG&PlusMinus'!$B$7:$E$912, 3, FALSE)), "", VLOOKUP(B15,'SOG&PlusMinus'!$B$7:$E$912, 3, FALSE)) -> A | M15: =IF(ISBLANK(VLOOKUP(B15, 'SOG&PlusMinus'!$B$7:$E$912, 4, FALSE)), "", VLOOKUP(B15, 'SOG&PlusMinus'!$B$7:$E$912, 4, FALSE)) -> 1 | N15: =VLOOKUP($B15, Paste!$A$3:$H$933, 5, FALSE) -> 20.121212 | O15: =IF(ISERROR(VLOOKUP(B15, Paste!$AB$3:$AE$2349, 3, FALSE)), "", VLOOKUP(B15, Paste!$AB$3:$AE$2349, 3, FALSE)) -> 33 | P15: =IF(ISERROR(VLOOKUP(B15, Paste!$AB$3:$AC$2343, 2, FALSE)), "", VLOOKUP(B15, Paste!$AB$3:$AC$2343, 2, FALSE)) -> 50 | Q15: =IF(ISERROR(VLOOKUP(B15, Paste!$AB$3:$AE$2349, 4, FALSE)), "", VLOOKUP(B15, Paste!$AB$3:$AE$2349, 4, FALSE)) -> 174 | R15: =IF(ISERROR(VLOOKUP(B15, Paste!$N$3:$N$250, 1, FALSE)), "", VLOOKUP(B15, Paste!$N$3:$O$250, 2, FALSE)) | S15: =VLOOKUP($B15, Paste!$W$3:$Z$10064, IF($H$4="Cap Hit",3, IF($H$4="AAV", 4, 2)), FALSE) -> 12 | T15: =IF(ISERROR(VLOOKUP(B15, Paste!$Q$3:$Q$245, 1, FALSE)), "", VLOOKUP(B15, Paste!$Q$3:$R$245, 2, FALSE)) | U15: =IF(VLOOKUP(B15, 'Points&Potential'!$B$7:$O$943, 14, FALSE)=0, "", VLOOKUP(B15, 'Points&Potential'!$B$7:$O$943, 14, FALSE)) | V15: =IF(ISERROR(VLOOKUP(B15, Paste!$T$3:$T$1045, 1, FALSE)), "", VLOOKUP(B15, Paste!$T$3:$U$1144, 2, FALSE))
A16: 10 | B16: Kirill Kaprizov | C16: =VLOOKUP(B16, Paste!$AG$3:$AH$2083, 2, FALSE) -> 29.1 | D16: =VLOOKUP($B16, Paste!$A$3:$H$933, 6, FALSE) -> LW | E16: =IFERROR(VLOOKUP($B16, Paste!$J$3:$L$933, 3, FALSE), "") -> 92 | F16: =IFERROR(VLOOKUP($B16, Paste!$J$3:$L$933, 2, FALSE), "") -> 120 | G16: =VLOOKUP($B16, Paste!$A$3:$H$933, 8, FALSE) -> MIN | H16: =VLOOKUP($B16, Paste!$A$3:$H$933, 2, FALSE) -> 76 | I16: =VLOOKUP($B16, Paste!$A$3:$H$933, 3, FALSE) -> 45.085074 | J16: =K16-I16 -> 51.181705 | K16: =VLOOKUP($B16, Paste!$A$3:$H$933, 4, FALSE) -> 96.266779 | L16: =IF(ISBLANK(VLOOKUP(B16, 'SOG&PlusMinus'!$B$7:$E$912, 3, FALSE)), "", VLOOKUP(B16,'SOG&PlusMinus'!$B$7:$E$912, 3, FALSE)) -> A | M16: =IF(ISBLANK(VLOOKUP(B16, 'SOG&PlusMinus'!$B$7:$E$912, 4, FALSE)), "", VLOOKUP(B16, 'SOG&PlusMinus'!$B$7:$E$912, 4, FALSE)) -> 1 | N16: =VLOOKUP($B16, Paste!$A$3:$H$933, 5, FALSE) -> 31.340206 | O16: =IF(ISERROR(VLOOKUP(B16, Paste!$AB$3:$AE$2349, 3, FALSE)), "", VLOOKUP(B16, Paste!$AB$3:$AE$2349, 3, FALSE)) -> 48 | P16: =IF(ISERROR(VLOOKUP(B16, Paste!$AB$3:$AC$2343, 2, FALSE)), "", VLOOKUP(B16, Paste!$AB$3:$AC$2343, 2, FALSE)) -> 33 | Q16: =IF(ISERROR(VLOOKUP(B16, Paste!$AB$3:$AE$2349, 4, FALSE)), "", VLOOKUP(B16, Paste!$AB$3:$AE$2349, 4, FALSE)) -> 266 | R16: =IF(ISERROR(VLOOKUP(B16, Paste!$N$3:$N$250, 1, FALSE)), "", VLOOKUP(B16, Paste!$N$3:$O$250, 2, FALSE)) | S16: =VLOOKUP($B16, Paste!$W$3:$Z$10064, IF($H$4="Cap Hit",3, IF($H$4="AAV", 4, 2)), FALSE) -> 17 | T16: =IF(ISERROR(VLOOKUP(B16, Paste!$Q$3:$Q$245, 1, FALSE)), "", VLOOKUP(B16, Paste!$Q$3:$R$245, 2, FALSE)) | U16: =IF(VLOOKUP(B16, 'Points&Potential'!$B$7:$O$943, 14, FALSE)=0, "", VLOOKUP(B16, 'Points&Potential'!$B$7:$O$943, 14, FALSE)) | V16: =IF(ISERROR(VLOOKUP(B16, Paste!$T$3:$T$1045, 1, FALSE)), "", VLOOKUP(B16, Paste!$T$3:$U$1144, 2, FALSE))
A17: 11 | B17: Nick Suzuki | C17: =VLOOKUP(B17, Paste!$AG$3:$AH$2083, 2, FALSE) -> 26.8 | D17: =VLOOKUP($B17, Paste!$A$3:$H$933, 6, FALSE) -> C | E17: =IFERROR(VLOOKUP($B17, Paste!$J$3:$L$933, 3, FALSE), "") -> 93 | F17: =IFERROR(VLOOKUP($B17, Paste!$J$3:$L$933, 2, FALSE), "") -> 105 | G17: =VLOOKUP($B17, Paste!$A$3:$H$933, 8, FALSE) -> MTL | H17: =VLOOKUP($B17, Paste!$A$3:$H$933, 2, FALSE) -> 84 | I17: =VLOOKUP($B17, Paste!$A$3:$H$933, 3, FALSE) -> 31.366018 | J17: =K17-I17 -> 64.403912 | K17: =VLOOKUP($B17, Paste!$A$3:$H$933, 4, FALSE) -> 95.769931 | L17: =IF(ISBLANK(VLOOKUP(B17, 'SOG&PlusMinus'!$B$7:$E$912, 3, FALSE)), "", VLOOKUP(B17,'SOG&PlusMinus'!$B$7:$E$912, 3, FALSE)) -> A | M17: =IF(ISBLANK(VLOOKUP(B17, 'SOG&PlusMinus'!$B$7:$E$912, 4, FALSE)), "", VLOOKUP(B17, 'SOG&PlusMinus'!$B$7:$E$912, 4, FALSE)) -> 1 | N17: =VLOOKUP($B17, Paste!$A$3:$H$933, 5, FALSE) -> 24.585366 | O17: =IF(ISERROR(VLOOKUP(B17, Paste!$AB$3:$AE$2349, 3, FALSE)), "", VLOOKUP(B17, Paste!$AB$3:$AE$2349, 3, FALSE)) -> 66 | P17: =IF(ISERROR(VLOOKUP(B17, Paste!$AB$3:$AC$2343, 2, FALSE)), "", VLOOKUP(B17, Paste!$AB$3:$AC$2343, 2, FALSE)) -> 59 | Q17: =IF(ISERROR(VLOOKUP(B17, Paste!$AB$3:$AE$2349, 4, FALSE)), "", VLOOKUP(B17, Paste!$AB$3:$AE$2349, 4, FALSE)) -> 185 | R17: =IF(ISERROR(VLOOKUP(B17, Paste!$N$3:$N$250, 1, FALSE)), "", VLOOKUP(B17, Paste!$N$3:$O$250, 2, FALSE)) | S17: =VLOOKUP($B17, Paste!$W$3:$Z$10064, IF($H$4="Cap Hit",3, IF($H$4="AAV", 4, 2)), FALSE) -> 7.875 | T17: =IF(ISERROR(VLOOKUP(B17, Paste!$Q$3:$Q$245, 1, FALSE)), "", VLOOKUP(B17, Paste!$Q$3:$R$245, 2, FALSE)) | U17: =IF(VLOOKUP(B17, 'Points&Potential'!$B$7:$O$943, 14, FALSE)=0, "", VLOOKUP(B17, 'Points&Potential'!$B$7:$O$943, 14, FALSE)) | V17: =IF(ISERROR(VLOOKUP(B17, Paste!$T$3:$T$1045, 1, FALSE)), "", VLOOKUP(B17, Paste!$T$3:$U$1144, 2, FALSE))
A18: 12 | B18: Kyle Connor | C18: =VLOOKUP(B18, Paste!$AG$3:$AH$2083, 2, FALSE) -> 29.5 | D18: =VLOOKUP($B18, Paste!$A$3:$H$933, 6, FALSE) -> LW | E18: =IFERROR(VLOOKUP($B18, Paste!$J$3:$L$933, 3, FALSE), "") -> 90 | F18: =IFERROR(VLOOKUP($B18, Paste!$J$3:$L$933, 2, FALSE), "") -> 100 | G18: =VLOOKUP($B18, Paste!$A$3:$H$933, 8, FALSE) -> WPG | H18: =VLOOKUP($B18, Paste!$A$3:$H$933, 2, FALSE) -> 84 | I18: =VLOOKUP($B18, Paste!$A$3:$H$933, 3, FALSE) -> 41.842637 | J18: =K18-I18 -> 53.884545 | K18: =VLOOKUP($B18, Paste!$A$3:$H$933, 4, FALSE) -> 95.727182 | L18: =IF(ISBLANK(VLOOKUP(B18, 'SOG&PlusMinus'!$B$7:$E$912, 3, FALSE)), "", VLOOKUP(B18,'SOG&PlusMinus'!$B$7:$E$912, 3, FALSE)) -> C | M18: =IF(ISBLANK(VLOOKUP(B18, 'SOG&PlusMinus'!$B$7:$E$912, 4, FALSE)), "", VLOOKUP(B18, 'SOG&PlusMinus'!$B$7:$E$912, 4, FALSE)) -> 1 | N18: =VLOOKUP($B18, Paste!$A$3:$H$933, 5, FALSE) -> 17.240175 | O18: =IF(ISERROR(VLOOKUP(B18, Paste!$AB$3:$AE$2349, 3, FALSE)), "", VLOOKUP(B18, Paste!$AB$3:$AE$2349, 3, FALSE)) -> 25 | P18: =IF(ISERROR(VLOOKUP(B18, Paste!$AB$3:$AC$2343, 2, FALSE)), "", VLOOKUP(B18, Paste!$AB$3:$AC$2343, 2, FALSE)) -> 25 | Q18: =IF(ISERROR(VLOOKUP(B18, Paste!$AB$3:$AE$2349, 4, FALSE)), "", VLOOKUP(B18, Paste!$AB$3:$AE$2349, 4, FALSE)) -> 277 | R18: =IF(ISERROR(VLOOKUP(B18, Paste!$N$3:$N$250, 1, FALSE)), "", VLOOKUP(B18, Paste!$N$3:$O$250, 2, FALSE)) | S18: =VLOOKUP($B18, Paste!$W$3:$Z$10064, IF($H$4="Cap Hit",3, IF($H$4="AAV", 4, 2)), FALSE) -> 12 | T18: =IF(ISERROR(VLOOKUP(B18, Paste!$Q$3:$Q$245, 1, FALSE)), "", VLOOKUP(B18, Paste!$Q$3:$R$245, 2, FALSE)) | U18: =IF(VLOOKUP(B18, 'Points&Potential'!$B$7:$O$943, 14, FALSE)=0, "", VLOOKUP(B18, 'Points&Potential'!$B$7:$O$943, 14, FALSE)) | V18: =IF(ISERROR(VLOOKUP(B18, Paste!$T$3:$T$1045, 1, FALSE)), "", VLOOKUP(B18, Paste!$T$3:$U$1144, 2, FALSE))
... A49: 43 | B49: Lane Hutson | C49: =VLOOKUP(B49, Paste!$AG$3:$AH$2083, 2, FALSE) -> 22.3 | D49: =VLOOKUP($B49, Paste!$A$3:$H$933, 6, FALSE) -> LD | E49: =IFERROR(VLOOKUP($B49, Paste!$J$3:$L$933, 3, FALSE), "") -> 80 | F49: =IFERROR(VLOOKUP($B49, Paste!$J$3:$L$933, 2, FALSE), "") -> 95 | G49: =VLOOKUP($B49, Paste!$A$3:$H$933, 8, FALSE) -> MTL | H49: =VLOOKUP($B49, Paste!$A$3:$H$933, 2, FALSE) -> 84 | I49: =VLOOKUP($B49, Paste!$A$3:$H$933, 3, FALSE) -> 6.2785208 | J49: =K49-I49 -> 72.286405 | K49: =VLOOKUP($B49, Paste!$A$3:$H$933, 4, FALSE) -> 78.564926 | L49: =IF(ISBLANK(VLOOKUP(B49, 'SOG&PlusMinus'!$B$7:$E$912, 3, FALSE)), "", VLOOKUP(B49,'SOG&PlusMinus'!$B$7:$E$912, 3, FALSE)) -> A | M49: =IF(ISBLANK(VLOOKUP(B49, 'SOG&PlusMinus'!$B$7:$E$912, 4, FALSE)), "", VLOOKUP(B49, 'SOG&PlusMinus'!$B$7:$E$912, 4, FALSE)) -> 1 | N49: =VLOOKUP($B49, Paste!$A$3:$H$933, 5, FALSE) -> 34.409639 | O49: =IF(ISERROR(VLOOKUP(B49, Paste!$AB$3:$AE$2349, 3, FALSE)), "", VLOOKUP(B49, Paste!$AB$3:$AE$2349, 3, FALSE)) -> 37 | P49: =IF(ISERROR(VLOOKUP(B49, Paste!$AB$3:$AC$2343, 2, FALSE)), "", VLOOKUP(B49, Paste!$AB$3:$AC$2343, 2, FALSE)) -> 126 | Q49: =IF(ISERROR(VLOOKUP(B49, Paste!$AB$3:$AE$2349, 4, FALSE)), "", VLOOKUP(B49, Paste!$AB$3:$AE$2349, 4, FALSE)) -> 134 | R49: =IF(ISERROR(VLOOKUP(B49, Paste!$N$3:$N$250, 1, FALSE)), "", VLOOKUP(B49, Paste!$N$3:$O$250, 2, FALSE)) | S49: =VLOOKUP($B49, Paste!$W$3:$Z$10064, IF($H$4="Cap Hit",3, IF($H$4="AAV", 4, 2)), FALSE) -> 8.85 | T49: =IF(ISERROR(VLOOKUP(B49, Paste!$Q$3:$Q$245, 1, FALSE)), "", VLOOKUP(B49, Paste!$Q$3:$R$245, 2, FALSE)) | U49: =IF(VLOOKUP(B49, 'Points&Potential'!$B$7:$O$943, 14, FALSE)=0, "", VLOOKUP(B49, 'Points&Potential'!$B$7:$O$943, 14, FALSE)) | V49: =IF(ISERROR(VLOOKUP(B49, Paste!$T$3:$T$1045, 1, FALSE)), "", VLOOKUP(B49, Paste!$T$3:$U$1144, 2, FALSE))
A50: 44 | B50: Sam Reinhart | C50: =VLOOKUP(B50, Paste!$AG$3:$AH$2083, 2, FALSE) -> 30.6 | D50: =VLOOKUP($B50, Paste!$A$3:$H$933, 6, FALSE) -> RW | E50: =IFERROR(VLOOKUP($B50, Paste!$J$3:$L$933, 3, FALSE), "") -> 87 | F50: =IFERROR(VLOOKUP($B50, Paste!$J$3:$L$933, 2, FALSE), "") -> 100 | G50: =VLOOKUP($B50, Paste!$A$3:$H$933, 8, FALSE) -> FLA | H50: =VLOOKUP($B50, Paste!$A$3:$H$933, 2, FALSE) -> 77 | I50: =VLOOKUP($B50, Paste!$A$3:$H$933, 3, FALSE) -> 41.272125 | J50: =K50-I50 -> 37.199264 | K50: =VLOOKUP($B50, Paste!$A$3:$H$933, 4, FALSE) -> 78.471388 | L50: =IF(ISBLANK(VLOOKUP(B50, 'SOG&PlusMinus'!$B$7:$E$912, 3, FALSE)), "", VLOOKUP(B50,'SOG&PlusMinus'!$B$7:$E$912, 3, FALSE)) -> C | M50: =IF(ISBLANK(VLOOKUP(B50, 'SOG&PlusMinus'!$B$7:$E$912, 4, FALSE)), "", VLOOKUP(B50, 'SOG&PlusMinus'!$B$7:$E$912, 4, FALSE)) -> 1 | N50: =VLOOKUP($B50, Paste!$A$3:$H$933, 5, FALSE) -> 22.33 | O50: =IF(ISERROR(VLOOKUP(B50, Paste!$AB$3:$AE$2349, 3, FALSE)), "", VLOOKUP(B50, Paste!$AB$3:$AE$2349, 3, FALSE)) -> 73 | P50: =IF(ISERROR(VLOOKUP(B50, Paste!$AB$3:$AC$2343, 2, FALSE)), "", VLOOKUP(B50, Paste!$AB$3:$AC$2343, 2, FALSE)) -> 54 | Q50: =IF(ISERROR(VLOOKUP(B50, Paste!$AB$3:$AE$2349, 4, FALSE)), "", VLOOKUP(B50, Paste!$AB$3:$AE$2349, 4, FALSE)) -> 208 | R50: =IF(ISERROR(VLOOKUP(B50, Paste!$N$3:$N$250, 1, FALSE)), "", VLOOKUP(B50, Paste!$N$3:$O$250, 2, FALSE)) | S50: =VLOOKUP($B50, Paste!$W$3:$Z$10064, IF($H$4="Cap Hit",3, IF($H$4="AAV", 4, 2)), FALSE) -> 8.625 | U50: =IF(VLOOKUP(B50, 'Points&Potential'!$B$7:$O$943, 14, FALSE)=0, "", VLOOKUP(B50, 'Points&Potential'!$B$7:$O$943, 14, FALSE)) | V50: =IF(ISERROR(VLOOKUP(B50, Paste!$T$3:$T$1045, 1, FALSE)), "", VLOOKUP(B50, Paste!$T$3:$U$1144, 2, FALSE))
A51: 45 | B51: Drake Batherson | C51: =VLOOKUP(B51, Paste!$AG$3:$AH$2083, 2, FALSE) -> 28.1 | D51: =VLOOKUP($B51, Paste!$A$3:$H$933, 6, FALSE) -> RW | E51: =IFERROR(VLOOKUP($B51, Paste!$J$3:$L$933, 3, FALSE), "") -> 75 | F51: =IFERROR(VLOOKUP($B51, Paste!$J$3:$L$933, 2, FALSE), "") -> 87 | G51: =VLOOKUP($B51, Paste!$A$3:$H$933, 8, FALSE) -> OTT | H51: =VLOOKUP($B51, Paste!$A$3:$H$933, 2, FALSE) -> 83 | I51: =VLOOKUP($B51, Paste!$A$3:$H$933, 3, FALSE) -> 30.71 | J51: =K51-I51 -> 47.728113 | K51: =VLOOKUP($B51, Paste!$A$3:$H$933, 4, FALSE) -> 78.438113 | L51: =IF(ISBLANK(VLOOKUP(B51, 'SOG&PlusMinus'!$B$7:$E$912, 3, FALSE)), "", VLOOKUP(B51,'SOG&PlusMinus'!$B$7:$E$912, 3, FALSE)) -> C | M51: =IF(ISBLANK(VLOOKUP(B51, 'SOG&PlusMinus'!$B$7:$E$912, 4, FALSE)), "", VLOOKUP(B51, 'SOG&PlusMinus'!$B$7:$E$912, 4, FALSE)) -> 1 | N51: =VLOOKUP($B51, Paste!$A$3:$H$933, 5, FALSE) -> 35.864198 | O51: =IF(ISERROR(VLOOKUP(B51, Paste!$AB$3:$AE$2349, 3, FALSE)), "", VLOOKUP(B51, Paste!$AB$3:$AE$2349, 3, FALSE)) -> 125 | P51: =IF(ISERROR(VLOOKUP(B51, Paste!$AB$3:$AC$2343, 2, FALSE)), "", VLOOKUP(B51, Paste!$AB$3:$AC$2343, 2, FALSE)) -> 29 | Q51: =IF(ISERROR(VLOOKUP(B51, Paste!$AB$3:$AE$2349, 4, FALSE)), "", VLOOKUP(B51, Paste!$AB$3:$AE$2349, 4, FALSE)) -> 191 | R51: =IF(ISERROR(VLOOKUP(B51, Paste!$N$3:$N$250, 1, FALSE)), "", VLOOKUP(B51, Paste!$N$3:$O$250, 2, FALSE)) | S51: =VLOOKUP($B51, Paste!$W$3:$Z$10064, IF($H$4="Cap Hit",3, IF($H$4="AAV", 4, 2)), FALSE) -> 4.975 | T51: =IF(ISERROR(VLOOKUP(B51, Paste!$Q$3:$Q$245, 1, FALSE)), "", VLOOKUP(B51, Paste!$Q$3:$R$245, 2, FALSE)) | U51: =IF(VLOOKUP(B51, 'Points&Potential'!$B$7:$O$943, 14, FALSE)=0, "", VLOOKUP(B51, 'Points&Potential'!$B$7:$O$943, 14, FALSE)) | V51: =IF(ISERROR(VLOOKUP(B51, Paste!$T$3:$T$1045, 1, FALSE)), "", VLOOKUP(B51, Paste!$T$3:$U$1144, 2, FALSE))
A52: 46 | B52: Lucas Raymond | C52: =VLOOKUP(B52, Paste!$AG$3:$AH$2083, 2, FALSE) -> 24.2 | D52: =VLOOKUP($B52, Paste!$A$3:$H$933, 6, FALSE) -> RW | E52: =IFERROR(VLOOKUP($B52, Paste!$J$3:$L$933, 3, FALSE), "") -> 80 | F52: =IFERROR(VLOOKUP($B52, Paste!$J$3:$L$933, 2, FALSE), "") -> 92 | G52: =VLOOKUP($B52, Paste!$A$3:$H$933, 8, FALSE) -> DET | H52: =VLOOKUP($B52, Paste!$A$3:$H$933, 2, FALSE) -> 76.666667 | I52: =VLOOKUP($B52, Paste!$A$3:$H$933, 3, FALSE) -> 26.638858 | J52: =K52-I52 -> 51.474436 | K52: =VLOOKUP($B52, Paste!$A$3:$H$933, 4, FALSE) -> 78.113295 | L52: =IF(ISBLANK(VLOOKUP(B52, 'SOG&PlusMinus'!$B$7:$E$912, 3, FALSE)), "", VLOOKUP(B52,'SOG&PlusMinus'!$B$7:$E$912, 3, FALSE)) -> C | M52: =IF(ISBLANK(VLOOKUP(B52, 'SOG&PlusMinus'!$B$7:$E$912, 4, FALSE)), "", VLOOKUP(B52, 'SOG&PlusMinus'!$B$7:$E$912, 4, FALSE)) -> 1 | N52: =VLOOKUP($B52, Paste!$A$3:$H$933, 5, FALSE) -> 21.994536 | O52: =IF(ISERROR(VLOOKUP(B52, Paste!$AB$3:$AE$2349, 3, FALSE)), "", VLOOKUP(B52, Paste!$AB$3:$AE$2349, 3, FALSE)) -> 41 | P52: =IF(ISERROR(VLOOKUP(B52, Paste!$AB$3:$AC$2343, 2, FALSE)), "", VLOOKUP(B52, Paste!$AB$3:$AC$2343, 2, FALSE)) -> 31 | Q52: =IF(ISERROR(VLOOKUP(B52, Paste!$AB$3:$AE$2349, 4, FALSE)), "", VLOOKUP(B52, Paste!$AB$3:$AE$2349, 4, FALSE)) -> 176 | R52: =IF(ISERROR(VLOOKUP(B52, Paste!$N$3:$N$250, 1, FALSE)), "", VLOOKUP(B52, Paste!$N$3:$O$250, 2, FALSE)) | S52: =VLOOKUP($B52, Paste!$W$3:$Z$10064, IF($H$4="Cap Hit",3, IF($H$4="AAV", 4, 2)), FALSE) -> 8.075 | T52: =IF(ISERROR(VLOOKUP(B52, Paste!$Q$3:$Q$245, 1, FALSE)), "", VLOOKUP(B52, Paste!$Q$3:$R$245, 2, FALSE)) | U52: =IF(VLOOKUP(B52, 'Points&Potential'!$B$7:$O$943, 14, FALSE)=0, "", VLOOKUP(B52, 'Points&Potential'!$B$7:$O$943, 14, FALSE)) | V52: =IF(ISERROR(VLOOKUP(B52, Paste!$T$3:$T$1045, 1, FALSE)), "", VLOOKUP(B52, Paste!$T$3:$U$1144, 2, FALSE))
A53: 47 | B53: Aleksander Barkov | C53: =VLOOKUP(B53, Paste!$AG$3:$AH$2083, 2, FALSE) -> 30.8 | D53: =VLOOKUP($B53, Paste!$A$3:$H$933, 6, FALSE) -> C | E53: =IFERROR(VLOOKUP($B53, Paste!$J$3:$L$933, 3, FALSE), "") -> 80 | F53: =IFERROR(VLOOKUP($B53, Paste!$J$3:$L$933, 2, FALSE), "") -> 100 | G53: =VLOOKUP($B53, Paste!$A$3:$H$933, 8, FALSE) -> FLA | H53: =VLOOKUP($B53, Paste!$A$3:$H$933, 2, FALSE) -> 75 | I53: =VLOOKUP($B53, Paste!$A$3:$H$933, 3, FALSE) -> 23.25 | J53: =K53-I53 -> 54.705961 | K53: =VLOOKUP($B53, Paste!$A$3:$H$933, 4, FALSE) -> 77.955961 | L53: =IF(ISBLANK(VLOOKUP(B53, 'SOG&PlusMinus'!$B$7:$E$912, 3, FALSE)), "", VLOOKUP(B53,'SOG&PlusMinus'!$B$7:$E$912, 3, FALSE)) -> B | M53: =IF(ISBLANK(VLOOKUP(B53, 'SOG&PlusMinus'!$B$7:$E$912, 4, FALSE)), "", VLOOKUP(B53, 'SOG&PlusMinus'!$B$7:$E$912, 4, FALSE)) -> 1 | N53: =VLOOKUP($B53, Paste!$A$3:$H$933, 5, FALSE) -> 18 | O53: =IF(ISERROR(VLOOKUP(B53, Paste!$AB$3:$AE$2349, 3, FALSE)), "", VLOOKUP(B53, Paste!$AB$3:$AE$2349, 3, FALSE)) -> 90 | P53: =IF(ISERROR(VLOOKUP(B53, Paste!$AB$3:$AC$2343, 2, FALSE)), "", VLOOKUP(B53, Paste!$AB$3:$AC$2343, 2, FALSE)) -> 53 | Q53: =IF(ISERROR(VLOOKUP(B53, Paste!$AB$3:$AE$2349, 4, FALSE)), "", VLOOKUP(B53, Paste!$AB$3:$AE$2349, 4, FALSE)) -> 165 | R53: =IF(ISERROR(VLOOKUP(B53, Paste!$N$3:$N$250, 1, FALSE)), "", VLOOKUP(B53, Paste!$N$3:$O$250, 2, FALSE)) | S53: =VLOOKUP($B53, Paste!$W$3:$Z$10064, IF($H$4="Cap Hit",3, IF($H$4="AAV", 4, 2)), FALSE) -> 10 | T53: =IF(ISERROR(VLOOKUP(B53, Paste!$Q$3:$Q$245, 1, FALSE)), "", VLOOKUP(B53, Paste!$Q$3:$R$245, 2, FALSE)) -> Y | U53: =IF(VLOOKUP(B53, 'Points&Potential'!$B$7:$O$943, 14, FALSE)=0, "", VLOOKUP(B53, 'Points&Potential'!$B$7:$O$943, 14, FALSE)) | V53: =IF(ISERROR(VLOOKUP(B53, Paste!$T$3:$T$1045, 1, FALSE)), "", VLOOKUP(B53, Paste!$T$3:$U$1144, 2, FALSE))
A54: 48 | B54: Filip Forsberg | C54: =VLOOKUP(B54, Paste!$AG$3:$AH$2083, 2, FALSE) -> 31.8 | D54: =VLOOKUP($B54, Paste!$A$3:$H$933, 6, FALSE) -> LW | E54: =IFERROR(VLOOKUP($B54, Paste!$J$3:$L$933, 3, FALSE), "") -> 75 | F54: =IFERROR(VLOOKUP($B54, Paste!$J$3:$L$933, 2, FALSE), "") -> 95 | G54: =VLOOKUP($B54, Paste!$A$3:$H$933, 8, FALSE) -> NSH | H54: =VLOOKUP($B54, Paste!$A$3:$H$933, 2, FALSE) -> 84 | I54: =VLOOKUP($B54, Paste!$A$3:$H$933, 3, FALSE) -> 38.547206 | J54: =K54-I54 -> 39.205226 | K54: =VLOOKUP($B54, Paste!$A$3:$H$933, 4, FALSE) -> 77.752432 | L54: =IF(ISBLANK(VLOOKUP(B54, 'SOG&PlusMinus'!$B$7:$E$912, 3, FALSE)), "", VLOOKUP(B54,'SOG&PlusMinus'!$B$7:$E$912, 3, FALSE)) -> C | M54: =IF(ISBLANK(VLOOKUP(B54, 'SOG&PlusMinus'!$B$7:$E$912, 4, FALSE)), "", VLOOKUP(B54, 'SOG&PlusMinus'!$B$7:$E$912, 4, FALSE)) -> 1 | N54: =VLOOKUP($B54, Paste!$A$3:$H$933, 5, FALSE) -> 41.317073 | O54: =IF(ISERROR(VLOOKUP(B54, Paste!$AB$3:$AE$2349, 3, FALSE)), "", VLOOKUP(B54, Paste!$AB$3:$AE$2349, 3, FALSE)) -> 134 | P54: =IF(ISERROR(VLOOKUP(B54, Paste!$AB$3:$AC$2343, 2, FALSE)), "", VLOOKUP(B54, Paste!$AB$3:$AC$2343, 2, FALSE)) -> 42 | Q54: =IF(ISERROR(VLOOKUP(B54, Paste!$AB$3:$AE$2349, 4, FALSE)), "", VLOOKUP(B54, Paste!$AB$3:$AE$2349, 4, FALSE)) -> 260 | R54: =IF(ISERROR(VLOOKUP(B54, Paste!$N$3:$N$250, 1, FALSE)), "", VLOOKUP(B54, Paste!$N$3:$O$250, 2, FALSE)) | S54: =VLOOKUP($B54, Paste!$W$3:$Z$10064, IF($H$4="Cap Hit",3, IF($H$4="AAV", 4, 2)), FALSE) -> 8.5 | T54: =IF(ISERROR(VLOOKUP(B54, Paste!$Q$3:$Q$245, 1, FALSE)), "", VLOOKUP(B54, Paste!$Q$3:$R$245, 2, FALSE)) | U54: =IF(VLOOKUP(B54, 'Points&Potential'!$B$7:$O$943, 14, FALSE)=0, "", VLOOKUP(B54, 'Points&Potential'!$B$7:$O$943, 14, FALSE)) | V54: =IF(ISERROR(VLOOKUP(B54, Paste!$T$3:$T$1045, 1, FALSE)), "", VLOOKUP(B54, Paste!$T$3:$U$1144, 2, FALSE))
A55: 49 | B55: Adrian Kempe | C55: =VLOOKUP(B55, Paste!$AG$3:$AH$2083, 2, FALSE) -> 29.8 | D55: =VLOOKUP($B55, Paste!$A$3:$H$933, 6, FALSE) -> RW | E55: =IFERROR(VLOOKUP($B55, Paste!$J$3:$L$933, 3, FALSE), "") -> 73 | F55: =IFERROR(VLOOKUP($B55, Paste!$J$3:$L$933, 2, FALSE), "") -> 83 | G55: =VLOOKUP($B55, Paste!$A$3:$H$933, 8, FALSE) -> LAK | H55: =VLOOKUP($B55, Paste!$A$3:$H$933, 2, FALSE) -> 81.666667 | I55: =VLOOKUP($B55, Paste!$A$3:$H$933, 3, FALSE) -> 33.253977 | J55: =K55-I55 -> 42.631833 | K55: =VLOOKUP($B55, Paste!$A$3:$H$933, 4, FALSE) -> 75.88581 | L55: =IF(ISBLANK(VLOOKUP(B55, 'SOG&PlusMinus'!$B$7:$E$912, 3, FALSE)), "", VLOOKUP(B55,'SOG&PlusMinus'!$B$7:$E$912, 3, FALSE)) -> A | M55: =IF(ISBLANK(VLOOKUP(B55, 'SOG&PlusMinus'!$B$7:$E$912, 4, FALSE)), "", VLOOKUP(B55, 'SOG&PlusMinus'!$B$7:$E$912, 4, FALSE)) -> 1 | N55: =VLOOKUP($B55, Paste!$A$3:$H$933, 5, FALSE) -> 56.722455 | O55: =IF(ISERROR(VLOOKUP(B55, Paste!$AB$3:$AE$2349, 3, FALSE)), "", VLOOKUP(B55, Paste!$AB$3:$AE$2349, 3, FALSE)) -> 123 | P55: =IF(ISERROR(VLOOKUP(B55, Paste!$AB$3:$AC$2343, 2, FALSE)), "", VLOOKUP(B55, Paste!$AB$3:$AC$2343, 2, FALSE)) -> 37 | Q55: =IF(ISERROR(VLOOKUP(B55, Paste!$AB$3:$AE$2349, 4, FALSE)), "", VLOOKUP(B55, Paste!$AB$3:$AE$2349, 4, FALSE)) -> 237 | R55: =IF(ISERROR(VLOOKUP(B55, Paste!$N$3:$N$250, 1, FALSE)), "", VLOOKUP(B55, Paste!$N$3:$O$250, 2, FALSE)) | S55: =VLOOKUP($B55, Paste!$W$3:$Z$10064, IF($H$4="Cap Hit",3, IF($H$4="AAV", 4, 2)), FALSE) -> 10.625 | T55: =IF(ISERROR(VLOOKUP(B55, Paste!$Q$3:$Q$245, 1, FALSE)), "", VLOOKUP(B55, Paste!$Q$3:$R$245, 2, FALSE)) | U55: =IF(VLOOKUP(B55, 'Points&Potential'!$B$7:$O$943, 14, FALSE)=0, "", VLOOKUP(B55, 'Points&Potential'!$B$7:$O$943, 14, FALSE)) | V55: =IF(ISERROR(VLOOKUP(B55, Paste!$T$3:$T$1045, 1, FALSE)), "", VLOOKUP(B55, Paste!$T$3:$U$1144, 2, FALSE))
A56: 50 | B56: Kirill Marchenko | C56: =VLOOKUP(B56, Paste!$AG$3:$AH$2083, 2, FALSE) -> 25.9 | D56: =VLOOKUP($B56, Paste!$A$3:$H$933, 6, FALSE) -> LW | E56: =IFERROR(VLOOKUP($B56, Paste!$J$3:$L$933, 3, FALSE), "") -> 75 | F56: =IFERROR(VLOOKUP($B56, Paste!$J$3:$L$933, 2, FALSE), "") -> 85 | G56: =VLOOKUP($B56, Paste!$A$3:$H$933, 8, FALSE) -> CBJ | H56: =VLOOKUP($B56, Paste!$A$3:$H$933, 2, FALSE) -> 79.666667 | I56: =VLOOKUP($B56, Paste!$A$3:$H$933, 3, FALSE) -> 28.371351 | J56: =K56-I56 -> 47.485345 | K56: =VLOOKUP($B56, Paste!$A$3:$H$933, 4, FALSE) -> 75.856695 | L56: =IF(ISBLANK(VLOOKUP(B56, 'SOG&PlusMinus'!$B$7:$E$912, 3, FALSE)), "", VLOOKUP(B56,'SOG&PlusMinus'!$B$7:$E$912, 3, FALSE)) -> C | M56: =IF(ISBLANK(VLOOKUP(B56, 'SOG&PlusMinus'!$B$7:$E$912, 4, FALSE)), "", VLOOKUP(B56, 'SOG&PlusMinus'!$B$7:$E$912, 4, FALSE)) -> 1 | N56: =VLOOKUP($B56, Paste!$A$3:$H$933, 5, FALSE) -> 22.566524 | O56: =IF(ISERROR(VLOOKUP(B56, Paste!$AB$3:$AE$2349, 3, FALSE)), "", VLOOKUP(B56, Paste!$AB$3:$AE$2349, 3, FALSE)) -> 60 | P56: =IF(ISERROR(VLOOKUP(B56, Paste!$AB$3:$AC$2343, 2, FALSE)), "", VLOOKUP(B56, Paste!$AB$3:$AC$2343, 2, FALSE)) -> 41 | Q56: =IF(ISERROR(VLOOKUP(B56, Paste!$AB$3:$AE$2349, 4, FALSE)), "", VLOOKUP(B56, Paste!$AB$3:$AE$2349, 4, FALSE)) -> 239 | R56: =IF(ISERROR(VLOOKUP(B56, Paste!$N$3:$N$250, 1, FALSE)), "", VLOOKUP(B56, Paste!$N$3:$O$250, 2, FALSE)) | S56: =VLOOKUP($B56, Paste!$W$3:$Z$10064, IF($H$4="Cap Hit",3, IF($H$4="AAV", 4, 2)), FALSE) -> 3.85 | T56: =IF(ISERROR(VLOOKUP(B56, Paste!$Q$3:$Q$245, 1, FALSE)), "", VLOOKUP(B56, Paste!$Q$3:$R$245, 2, FALSE)) | U56: =IF(VLOOKUP(B56, 'Points&Potential'!$B$7:$O$943, 14, FALSE)=0, "", VLOOKUP(B56, 'Points&Potential'!$B$7:$O$943, 14, FALSE)) | V56: =IF(ISERROR(VLOOKUP(B56, Paste!$T$3:$T$1045, 1, FALSE)), "", VLOOKUP(B56, Paste!$T$3:$U$1144, 2, FALSE))
A57: 51 | B57: Ivan Demidov | C57: =VLOOKUP(B57, Paste!$AG$3:$AH$2083, 2, FALSE) -> 20.5 | D57: =VLOOKUP($B57, Paste!$A$3:$H$933, 6, FALSE) -> RW | E57: =IFERROR(VLOOKUP($B57, Paste!$J$3:$L$933, 3, FALSE), "") -> 80 | F57: =IFERROR(VLOOKUP($B57, Paste!$J$3:$L$933, 2, FALSE), "") -> 110 | G57: =VLOOKUP($B57, Paste!$A$3:$H$933, 8, FALSE) -> MTL | H57: =VLOOKUP($B57, Paste!$A$3:$H$933, 2, FALSE) -> 82 | I57: =VLOOKUP($B57, Paste!$A$3:$H$933, 3, FALSE) -> 27.881102 | J57: =K57-I57 -> 47.588134 | K57: =VLOOKUP($B57, Paste!$A$3:$H$933, 4, FALSE) -> 75.469236 | L57: =IF(ISBLANK(VLOOKUP(B57, 'SOG&PlusMinus'!$B$7:$E$912, 3, FALSE)), "", VLOOKUP(B57,'SOG&PlusMinus'!$B$7:$E$912, 3, FALSE)) -> C | M57: =IF(ISBLANK(VLOOKUP(B57, 'SOG&PlusMinus'!$B$7:$E$912, 4, FALSE)), "", VLOOKUP(B57, 'SOG&PlusMinus'!$B$7:$E$912, 4, FALSE)) -> 1 | N57: =VLOOKUP($B57, Paste!$A$3:$H$933, 5, FALSE) -> 22.126984 | O57: =IF(ISERROR(VLOOKUP(B57, Paste!$AB$3:$AE$2349, 3, FALSE)), "", VLOOKUP(B57, Paste!$AB$3:$AE$2349, 3, FALSE)) -> 32 | P57: =IF(ISERROR(VLOOKUP(B57, Paste!$AB$3:$AC$2343, 2, FALSE)), "", VLOOKUP(B57, Paste!$AB$3:$AC$2343, 2, FALSE)) -> 29 | Q57: =IF(ISERROR(VLOOKUP(B57, Paste!$AB$3:$AE$2349, 4, FALSE)), "", VLOOKUP(B57, Paste!$AB$3:$AE$2349, 4, FALSE)) -> 156 | R57: =IF(ISERROR(VLOOKUP(B57, Paste!$N$3:$N$250, 1, FALSE)), "", VLOOKUP(B57, Paste!$N$3:$O$250, 2, FALSE)) | S57: =VLOOKUP($B57, Paste!$W$3:$Z$10064, IF($H$4="Cap Hit",3, IF($H$4="AAV", 4, 2)), FALSE) -> 2.634167 | T57: =IF(ISERROR(VLOOKUP(B57, Paste!$Q$3:$Q$245, 1, FALSE)), "", VLOOKUP(B57, Paste!$Q$3:$R$245, 2, FALSE)) | U57: =IF(VLOOKUP(B57, 'Points&Potential'!$B$7:$O$943, 14, FALSE)=0, "", VLOOKUP(B57, 'Points&Potential'!$B$7:$O$943, 14, FALSE)) | V57: =IF(ISERROR(VLOOKUP(B57, Paste!$T$3:$T$1045, 1, FALSE)), "", VLOOKUP(B57, Paste!$T$3:$U$1144, 2, FALSE))
A58: 52 | B58: Rasmus Dahlin | C58: =VLOOKUP(B58, Paste!$AG$3:$AH$2083, 2, FALSE) -> 26.2 | D58: =VLOOKUP($B58, Paste!$A$3:$H$933, 6, FALSE) -> LD | E58: =IFERROR(VLOOKUP($B58, Paste!$J$3:$L$933, 3, FALSE), "") -> 77 | F58: =IFERROR(VLOOKUP($B58, Paste!$J$3:$L$933, 2, FALSE), "") -> 95 | G58: =VLOOKUP($B58, Paste!$A$3:$H$933, 8, FALSE) -> BUF | H58: =VLOOKUP($B58, Paste!$A$3:$H$933, 2, FALSE) -> 79 | I58: =VLOOKUP($B58, Paste!$A$3:$H$933, 3, FALSE) -> 18.751072 | J58: =K58-I58 -> 56.662537 | K58: =VLOOKUP($B58, Paste!$A$3:$H$933, 4, FALSE) -> 75.413608 | L58: =IF(ISBLANK(VLOOKUP(B58, 'SOG&PlusMinus'!$B$7:$E$912, 3, FALSE)), "", VLOOKUP(B58,'SOG&PlusMinus'!$B$7:$E$912, 3, FALSE)) -> A | M58: =IF(ISBLANK(VLOOKUP(B58, 'SOG&PlusMinus'!$B$7:$E$912, 4, FALSE)), "", VLOOKUP(B58, 'SOG&PlusMinus'!$B$7:$E$912, 4, FALSE)) -> 1 | N58: =VLOOKUP($B58, Paste!$A$3:$H$933, 5, FALSE) -> 67.030303 | O58: =IF(ISERROR(VLOOKUP(B58, Paste!$AB$3:$AE$2349, 3, FALSE)), "", VLOOKUP(B58, Paste!$AB$3:$AE$2349, 3, FALSE)) -> 82 | P58: =IF(ISERROR(VLOOKUP(B58, Paste!$AB$3:$AC$2343, 2, FALSE)), "", VLOOKUP(B58, Paste!$AB$3:$AC$2343, 2, FALSE)) -> 114 | Q58: =IF(ISERROR(VLOOKUP(B58, Paste!$AB$3:$AE$2349, 4, FALSE)), "", VLOOKUP(B58, Paste!$AB$3:$AE$2349, 4, FALSE)) -> 213 | R58: =IF(ISERROR(VLOOKUP(B58, Paste!$N$3:$N$250, 1, FALSE)), "", VLOOKUP(B58, Paste!$N$3:$O$250, 2, FALSE)) | S58: =VLOOKUP($B58, Paste!$W$3:$Z$10064, IF($H$4="Cap Hit",3, IF($H$4="AAV", 4, 2)), FALSE) -> 11 | U58: =IF(VLOOKUP(B58, 'Points&Potential'!$B$7:$O$943, 14, FALSE)=0, "", VLOOKUP(B58, 'Points&Potential'!$B$7:$O$943, 14, FALSE)) | V58: =IF(ISERROR(VLOOKUP(B58, Paste!$T$3:$T$1045, 1, FALSE)), "", VLOOKUP(B58, Paste!$T$3:$U$1144, 2, FALSE))
A59: 53 | B59: Leo Carlsson | C59: =VLOOKUP(B59, Paste!$AG$3:$AH$2083, 2, FALSE) -> 21.5 | D59: =VLOOKUP($B59, Paste!$A$3:$H$933, 6, FALSE) -> C | E59: =IFERROR(VLOOKUP($B59, Paste!$J$3:$L$933, 3, FALSE), "") -> 85 | F59: =IFERROR(VLOOKUP($B59, Paste!$J$3:$L$933, 2, FALSE), "") -> 100 | G59: =VLOOKUP($B59, Paste!$A$3:$H$933, 8, FALSE) -> ANA | H59: =VLOOKUP($B59, Paste!$A$3:$H$933, 2, FALSE) -> 72 | I59: =VLOOKUP($B59, Paste!$A$3:$H$933, 3, FALSE) -> 32.4 | J59: =K59-I59 -> 41.73705 | K59: =VLOOKUP($B59, Paste!$A$3:$H$933, 4, FALSE) -> 74.13705 | L59: =IF(ISBLANK(VLOOKUP(B59, 'SOG&PlusMinus'!$B$7:$E$912, 3, FALSE)), "", VLOOKUP(B59,'SOG&PlusMinus'!$B$7:$E$912, 3, FALSE)) -> C | M59: =IF(ISBLANK(VLOOKUP(B59, 'SOG&PlusMinus'!$B$7:$E$912, 4, FALSE)), "", VLOOKUP(B59, 'SOG&PlusMinus'!$B$7:$E$912, 4, FALSE)) -> 1 | N59: =VLOOKUP($B59, Paste!$A$3:$H$933, 5, FALSE) -> 22.567164 | O59: =IF(ISERROR(VLOOKUP(B59, Paste!$AB$3:$AE$2349, 3, FALSE)), "", VLOOKUP(B59, Paste!$AB$3:$AE$2349, 3, FALSE)) -> 22 | P59: =IF(ISERROR(VLOOKUP(B59, Paste!$AB$3:$AC$2343, 2, FALSE)), "", VLOOKUP(B59, Paste!$AB$3:$AC$2343, 2, FALSE)) -> 33 | Q59: =IF(ISERROR(VLOOKUP(B59, Paste!$AB$3:$AE$2349, 4, FALSE)), "", VLOOKUP(B59, Paste!$AB$3:$AE$2349, 4, FALSE)) -> 209 | R59: =IF(ISERROR(VLOOKUP(B59, Paste!$N$3:$N$250, 1, FALSE)), "", VLOOKUP(B59, Paste!$N$3:$O$250, 2, FALSE)) -> 85 | S59: =VLOOKUP($B59, Paste!$W$3:$Z$10064, IF($H$4="Cap Hit",3, IF($H$4="AAV", 4, 2)), FALSE) -> 18 | T59: =IF(ISERROR(VLOOKUP(B59, Paste!$Q$3:$Q$245, 1, FALSE)), "", VLOOKUP(B59, Paste!$Q$3:$R$245, 2, FALSE)) -> Y | U59: =IF(VLOOKUP(B59, 'Points&Potential'!$B$7:$O$943, 14, FALSE)=0, "", VLOOKUP(B59, 'Points&Potential'!$B$7:$O$943, 14, FALSE)) | V59: =IF(ISERROR(VLOOKUP(B59, Paste!$T$3:$T$1045, 1, FALSE)), "", VLOOKUP(B59, Paste!$T$3:$U$1144, 2, FALSE))
A60: 54 | B60: Mika Zibanejad | C60: =VLOOKUP(B60, Paste!$AG$3:$AH$2083, 2, FALSE) -> 33.2 | D60: =VLOOKUP($B60, Paste!$A$3:$H$933, 6, FALSE) -> C | E60: =IFERROR(VLOOKUP($B60, Paste!$J$3:$L$933, 3, FALSE), "") -> 67 | F60: =IFERROR(VLOOKUP($B60, Paste!$J$3:$L$933, 2, FALSE), "") -> 75 | G60: =VLOOKUP($B60, Paste!$A$3:$H$933, 8, FALSE) -> NYR | H60: =VLOOKUP($B60, Paste!$A$3:$H$933, 2, FALSE) -> 83.333333 | I60: =VLOOKUP($B60, Paste!$A$3:$H$933, 3, FALSE) -> 27.015907 | J60: =K60-I60 -> 46.780389 | K60: =VLOOKUP($B60, Paste!$A$3:$H$933, 4, FALSE) -> 73.796297 | L60: =IF(ISBLANK(VLOOKUP(B60, 'SOG&PlusMinus'!$B$7:$E$912, 3, FALSE)), "", VLOOKUP(B60,'SOG&PlusMinus'!$B$7:$E$912, 3, FALSE)) -> D | M60: =IF(ISBLANK(VLOOKUP(B60, 'SOG&PlusMinus'!$B$7:$E$912, 4, FALSE)), "", VLOOKUP(B60, 'SOG&PlusMinus'!$B$7:$E$912, 4, FALSE)) -> 1 | N60: =VLOOKUP($B60, Paste!$A$3:$H$933, 5, FALSE) -> 22.540984 | O60: =IF(ISERROR(VLOOKUP(B60, Paste!$AB$3:$AE$2349, 3, FALSE)), "", VLOOKUP(B60, Paste!$AB$3:$AE$2349, 3, FALSE)) -> 68 | P60: =IF(ISERROR(VLOOKUP(B60, Paste!$AB$3:$AC$2343, 2, FALSE)), "", VLOOKUP(B60, Paste!$AB$3:$AC$2343, 2, FALSE)) -> 52 | Q60: =IF(ISERROR(VLOOKUP(B60, Paste!$AB$3:$AE$2349, 4, FALSE)), "", VLOOKUP(B60, Paste!$AB$3:$AE$2349, 4, FALSE)) -> 208 | R60: =IF(ISERROR(VLOOKUP(B60, Paste!$N$3:$N$250, 1, FALSE)), "", VLOOKUP(B60, Paste!$N$3:$O$250, 2, FALSE)) | S60: =VLOOKUP($B60, Paste!$W$3:$Z$10064, IF($H$4="Cap Hit",3, IF($H$4="AAV", 4, 2)), FALSE) -> 8.5 | T60: =IF(ISERROR(VLOOKUP(B60, Paste!$Q$3:$Q$245, 1, FALSE)), "", VLOOKUP(B60, Paste!$Q$3:$R$245, 2, FALSE)) | U60: =IF(VLOOKUP(B60, 'Points&Potential'!$B$7:$O$943, 14, FALSE)=0, "", VLOOKUP(B60, 'Points&Potential'!$B$7:$O$943, 14, FALSE)) | V60: =IF(ISERROR(VLOOKUP(B60, Paste!$T$3:$T$1045, 1, FALSE)), "", VLOOKUP(B60, Paste!$T$3:$U$1144, 2, FALSE))
A61: 55 | B61: Cutter Gauthier | C61: =VLOOKUP(B61, Paste!$AG$3:$AH$2083, 2, FALSE) -> 22.4 | D61: =VLOOKUP($B61, Paste!$A$3:$H$933, 6, FALSE) -> RW | E61: =IFERROR(VLOOKUP($B61, Paste!$J$3:$L$933, 3, FALSE), "") -> 77 | F61: =IFERROR(VLOOKUP($B61, Paste!$J$3:$L$933, 2, FALSE), "") -> 92 | G61: =VLOOKUP($B61, Paste!$A$3:$H$933, 8, FALSE) -> ANA | H61: =VLOOKUP($B61, Paste!$A$3:$H$933, 2, FALSE) -> 79 | I61: =VLOOKUP($B61, Paste!$A$3:$H$933, 3, FALSE) -> 41.08 | J61: =K61-I61 -> 32.49902 | K61: =VLOOKUP($B61, Paste!$A$3:$H$933, 4, FALSE) -> 73.57902 | L61: =IF(ISBLANK(VLOOKUP(B61, 'SOG&PlusMinus'!$B$7:$E$912, 3, FALSE)), "", VLOOKUP(B61,'SOG&PlusMinus'!$B$7:$E$912, 3, FALSE)) -> C | M61: =IF(ISBLANK(VLOOKUP(B61, 'SOG&PlusMinus'!$B$7:$E$912, 4, FALSE)), "", VLOOKUP(B61, 'SOG&PlusMinus'!$B$7:$E$912, 4, FALSE)) -> 1 | N61: =VLOOKUP($B61, Paste!$A$3:$H$933, 5, FALSE) -> 23.849057 | O61: =IF(ISERROR(VLOOKUP(B61, Paste!$AB$3:$AE$2349, 3, FALSE)), "", VLOOKUP(B61, Paste!$AB$3:$AE$2349, 3, FALSE)) -> 67 | P61: =IF(ISERROR(VLOOKUP(B61, Paste!$AB$3:$AC$2343, 2, FALSE)), "", VLOOKUP(B61, Paste!$AB$3:$AC$2343, 2, FALSE)) -> 32 | Q61: =IF(ISERROR(VLOOKUP(B61, Paste!$AB$3:$AE$2349, 4, FALSE)), "", VLOOKUP(B61, Paste!$AB$3:$AE$2349, 4, FALSE)) -> 316 | R61: =IF(ISERROR(VLOOKUP(B61, Paste!$N$3:$N$250, 1, FALSE)), "", VLOOKUP(B61, Paste!$N$3:$O$250, 2, FALSE)) | S61: =VLOOKUP($B61, Paste!$W$3:$Z$10064, IF($H$4="Cap Hit",3, IF($H$4="AAV", 4, 2)), FALSE) -> #N/A | T61: =IF(ISERROR(VLOOKUP(B61, Paste!$Q$3:$Q$245, 1, FALSE)), "", VLOOKUP(B61, Paste!$Q$3:$R$245, 2, FALSE)) | U61: =IF(VLOOKUP(B61, 'Points&Potential'!$B$7:$O$943, 14, FALSE)=0, "", VLOOKUP(B61, 'Points&Potential'!$B$7:$O$943, 14, FALSE)) | V61: =IF(ISERROR(VLOOKUP(B61, Paste!$T$3:$T$1045, 1, FALSE)), "", VLOOKUP(B61, Paste!$T$3:$U$1144, 2, FALSE))
A62: 56 | B62: Brady Tkachuk | C62: =VLOOKUP(B62, Paste!$AG$3:$AH$2083, 2, FALSE) -> 26.7 | D62: =VLOOKUP($B62, Paste!$A$3:$H$933, 6, FALSE) -> LW | E62: =IFERROR(VLOOKUP($B62, Paste!$J$3:$L$933, 3, FALSE), "") -> 82 | F62: =IFERROR(VLOOKUP($B62, Paste!$J$3:$L$933, 2, FALSE), "") -> 97 | G62: =VLOOKUP($B62, Paste!$A$3:$H$933, 8, FALSE) -> FLA | H62: =VLOOKUP($B62, Paste!$A$3:$H$933, 2, FALSE) -> 73 | I62: =VLOOKUP($B62, Paste!$A$3:$H$933, 3, FALSE) -> 30.66 | J62: =K62-I62 -> 41.965545 | K62: =VLOOKUP($B62, Paste!$A$3:$H$933, 4, FALSE) -> 72.625545 | L62: =IF(ISBLANK(VLOOKUP(B62, 'SOG&PlusMinus'!$B$7:$E$912, 3, FALSE)), "", VLOOKUP(B62,'SOG&PlusMinus'!$B$7:$E$912, 3, FALSE)) -> C | M62: =IF(ISBLANK(VLOOKUP(B62, 'SOG&PlusMinus'!$B$7:$E$912, 4, FALSE)), "", VLOOKUP(B62, 'SOG&PlusMinus'!$B$7:$E$912, 4, FALSE)) -> 1 | N62: =VLOOKUP($B62, Paste!$A$3:$H$933, 5, FALSE) -> 124.1 | O62: =IF(ISERROR(VLOOKUP(B62, Paste!$AB$3:$AE$2349, 3, FALSE)), "", VLOOKUP(B62, Paste!$AB$3:$AE$2349, 3, FALSE)) -> 217 | P62: =IF(ISERROR(VLOOKUP(B62, Paste!$AB$3:$AC$2343, 2, FALSE)), "", VLOOKUP(B62, Paste!$AB$3:$AC$2343, 2, FALSE)) -> 29 | Q62: =IF(ISERROR(VLOOKUP(B62, Paste!$AB$3:$AE$2349, 4, FALSE)), "", VLOOKUP(B62, Paste!$AB$3:$AE$2349, 4, FALSE)) -> 263 | R62: =IF(ISERROR(VLOOKUP(B62, Paste!$N$3:$N$250, 1, FALSE)), "", VLOOKUP(B62, Paste!$N$3:$O$250, 2, FALSE)) | S62: =VLOOKUP($B62, Paste!$W$3:$Z$10064, IF($H$4="Cap Hit",3, IF($H$4="AAV", 4, 2)), FALSE) -> 8.205714 | T62: =IF(ISERROR(VLOOKUP(B62, Paste!$Q$3:$Q$245, 1, FALSE)), "", VLOOKUP(B62, Paste!$Q$3:$R$245, 2, FALSE)) -> Y | U62: =IF(VLOOKUP(B62, 'Points&Potential'!$B$7:$O$943, 14, FALSE)=0, "", VLOOKUP(B62, 'Points&Potential'!$B$7:$O$943, 14, FALSE)) | V62: =IF(ISERROR(VLOOKUP(B62, Paste!$T$3:$T$1045, 1, FALSE)), "", VLOOKUP(B62, Paste!$T$3:$U$1144, 2, FALSE))
A63: 57 | B63: Nikolaj Ehlers | C63: =VLOOKUP(B63, Paste!$AG$3:$AH$2083, 2, FALSE) -> 30.3 | D63: =VLOOKUP($B63, Paste!$A$3:$H$933, 6, FALSE) -> LW | E63: =IFERROR(VLOOKUP($B63, Paste!$J$3:$L$933, 3, FALSE), "") -> 73 | F63: =IFERROR(VLOOKUP($B63, Paste!$J$3:$L$933, 2, FALSE), "") -> 83 | G63: =VLOOKUP($B63, Paste!$A$3:$H$933, 8, FALSE) -> CAR | H63: =VLOOKUP($B63, Paste!$A$3:$H$933, 2, FALSE) -> 81 | I63: =VLOOKUP($B63, Paste!$A$3:$H$933, 3, FALSE) -> 26.73 | J63: =K63-I63 -> 45.354735 | K63: =VLOOKUP($B63, Paste!$A$3:$H$933, 4, FALSE) -> 72.084735 | L63: =IF(ISBLANK(VLOOKUP(B63, 'SOG&PlusMinus'!$B$7:$E$912, 3, FALSE)), "", VLOOKUP(B63,'SOG&PlusMinus'!$B$7:$E$912, 3, FALSE)) -> B | M63: =IF(ISBLANK(VLOOKUP(B63, 'SOG&PlusMinus'!$B$7:$E$912, 4, FALSE)), "", VLOOKUP(B63, 'SOG&PlusMinus'!$B$7:$E$912, 4, FALSE)) -> 1 | N63: =VLOOKUP($B63, Paste!$A$3:$H$933, 5, FALSE) -> 20.858369 | O63: =IF(ISERROR(VLOOKUP(B63, Paste!$AB$3:$AE$2349, 3, FALSE)), "", VLOOKUP(B63, Paste!$AB$3:$AE$2349, 3, FALSE)) -> 24 | P63: =IF(ISERROR(VLOOKUP(B63, Paste!$AB$3:$AC$2343, 2, FALSE)), "", VLOOKUP(B63, Paste!$AB$3:$AC$2343, 2, FALSE)) -> 24 | Q63: =IF(ISERROR(VLOOKUP(B63, Paste!$AB$3:$AE$2349, 4, FALSE)), "", VLOOKUP(B63, Paste!$AB$3:$AE$2349, 4, FALSE)) -> 194 | R63: =IF(ISERROR(VLOOKUP(B63, Paste!$N$3:$N$250, 1, FALSE)), "", VLOOKUP(B63, Paste!$N$3:$O$250, 2, FALSE)) | S63: =VLOOKUP($B63, Paste!$W$3:$Z$10064, IF($H$4="Cap Hit",3, IF($H$4="AAV", 4, 2)), FALSE) -> 8.5 | T63: =IF(ISERROR(VLOOKUP(B63, Paste!$Q$3:$Q$245, 1, FALSE)), "", VLOOKUP(B63, Paste!$Q$3:$R$245, 2, FALSE)) | U63: =IF(VLOOKUP(B63, 'Points&Potential'!$B$7:$O$943, 14, FALSE)=0, "", VLOOKUP(B63, 'Points&Potential'!$B$7:$O$943, 14, FALSE)) | V63: =IF(ISERROR(VLOOKUP(B63, Paste!$T$3:$T$1045, 1, FALSE)), "", VLOOKUP(B63, Paste!$T$3:$U$1144, 2, FALSE))
A64: 58 | B64: Gabriel Vilardi | C64: =VLOOKUP(B64, Paste!$AG$3:$AH$2083, 2, FALSE) -> 26.8 | D64: =VLOOKUP($B64, Paste!$A$3:$H$933, 6, FALSE) -> RW | E64: =IFERROR(VLOOKUP($B64, Paste!$J$3:$L$933, 3, FALSE), "") -> 68 | F64: =IFERROR(VLOOKUP($B64, Paste!$J$3:$L$933, 2, FALSE), "") -> 80 | G64: =VLOOKUP($B64, Paste!$A$3:$H$933, 8, FALSE) -> WPG | H64: =VLOOKUP($B64, Paste!$A$3:$H$933, 2, FALSE) -> 75 | I64: =VLOOKUP($B64, Paste!$A$3:$H$933, 3, FALSE) -> 28.890596 | J64: =K64-I64 -> 42.748763 | K64: =VLOOKUP($B64, Paste!$A$3:$H$933, 4, FALSE) -> 71.639359 | L64: =IF(ISBLANK(VLOOKUP(B64, 'SOG&PlusMinus'!$B$7:$E$912, 3, FALSE)), "", VLOOKUP(B64,'SOG&PlusMinus'!$B$7:$E$912, 3, FALSE)) -> D | M64: =IF(ISBLANK(VLOOKUP(B64, 'SOG&PlusMinus'!$B$7:$E$912, 4, FALSE)), "", VLOOKUP(B64, 'SOG&PlusMinus'!$B$7:$E$912, 4, FALSE)) -> 1 | N64: =VLOOKUP($B64, Paste!$A$3:$H$933, 5, FALSE) -> 19.5 | O64: =IF(ISERROR(VLOOKUP(B64, Paste!$AB$3:$AE$2349, 3, FALSE)), "", VLOOKUP(B64, Paste!$AB$3:$AE$2349, 3, FALSE)) -> 23 | P64: =IF(ISERROR(VLOOKUP(B64, Paste!$AB$3:$AC$2343, 2, FALSE)), "", VLOOKUP(B64, Paste!$AB$3:$AC$2343, 2, FALSE)) -> 38 | Q64: =IF(ISERROR(VLOOKUP(B64, Paste!$AB$3:$AE$2349, 4, FALSE)), "", VLOOKUP(B64, Paste!$AB$3:$AE$2349, 4, FALSE)) -> 143 | R64: =IF(ISERROR(VLOOKUP(B64, Paste!$N$3:$N$250, 1, FALSE)), "", VLOOKUP(B64, Paste!$N$3:$O$250, 2, FALSE)) | S64: =VLOOKUP($B64, Paste!$W$3:$Z$10064, IF($H$4="Cap Hit",3, IF($H$4="AAV", 4, 2)), FALSE) -> 7.5 | T64: =IF(ISERROR(VLOOKUP(B64, Paste!$Q$3:$Q$245, 1, FALSE)), "", VLOOKUP(B64, Paste!$Q$3:$R$245, 2, FALSE)) -> Y | U64: =IF(VLOOKUP(B64, 'Points&Potential'!$B$7:$O$943, 14, FALSE)=0, "", VLOOKUP(B64, 'Points&Potential'!$B$7:$O$943, 14, FALSE)) | V64: =IF(ISERROR(VLOOKUP(B64, Paste!$T$3:$T$1045, 1, FALSE)), "", VLOOKUP(B64, Paste!$T$3:$U$1144, 2, FALSE))
A65: 59 | B65: Alexis Lafreniere | C65: =VLOOKUP(B65, Paste!$AG$3:$AH$2083, 2, FALSE) -> 24.7 | D65: =VLOOKUP($B65, Paste!$A$3:$H$933, 6, FALSE) -> RW | E65: =IFERROR(VLOOKUP($B65, Paste!$J$3:$L$933, 3, FALSE), "") -> 70 | F65: =IFERROR(VLOOKUP($B65, Paste!$J$3:$L$933, 2, FALSE), "") -> 85 | G65: =VLOOKUP($B65, Paste!$A$3:$H$933, 8, FALSE) -> NYR | H65: =VLOOKUP($B65, Paste!$A$3:$H$933, 2, FALSE) -> 84 | I65: =VLOOKUP($B65, Paste!$A$3:$H$933, 3, FALSE) -> 33.6 | J65: =K65-I65 -> 38.01784 | K65: =VLOOKUP($B65, Paste!$A$3:$H$933, 4, FALSE) -> 71.61784 | L65: =IF(ISBLANK(VLOOKUP(B65, 'SOG&PlusMinus'!$B$7:$E$912, 3, FALSE)), "", VLOOKUP(B65,'SOG&PlusMinus'!$B$7:$E$912, 3, FALSE)) -> C | M65: =IF(ISBLANK(VLOOKUP(B65, 'SOG&PlusMinus'!$B$7:$E$912, 4, FALSE)), "", VLOOKUP(B65, 'SOG&PlusMinus'!$B$7:$E$912, 4, FALSE)) -> 1 | N65: =VLOOKUP($B65, Paste!$A$3:$H$933, 5, FALSE) -> 33.463415 | O65: =IF(ISERROR(VLOOKUP(B65, Paste!$AB$3:$AE$2349, 3, FALSE)), "", VLOOKUP(B65, Paste!$AB$3:$AE$2349, 3, FALSE)) -> 94 | P65: =IF(ISERROR(VLOOKUP(B65, Paste!$AB$3:$AC$2343, 2, FALSE)), "", VLOOKUP(B65, Paste!$AB$3:$AC$2343, 2, FALSE)) -> 42 | Q65: =IF(ISERROR(VLOOKUP(B65, Paste!$AB$3:$AE$2349, 4, FALSE)), "", VLOOKUP(B65, Paste!$AB$3:$AE$2349, 4, FALSE)) -> 218 | R65: =IF(ISERROR(VLOOKUP(B65, Paste!$N$3:$N$250, 1, FALSE)), "", VLOOKUP(B65, Paste!$N$3:$O$250, 2, FALSE)) -> 80 | S65: =VLOOKUP($B65, Paste!$W$3:$Z$10064, IF($H$4="Cap Hit",3, IF($H$4="AAV", 4, 2)), FALSE) -> 7.45 | T65: =IF(ISERROR(VLOOKUP(B65, Paste!$Q$3:$Q$245, 1, FALSE)), "", VLOOKUP(B65, Paste!$Q$3:$R$245, 2, FALSE)) | U65: =IF(VLOOKUP(B65, 'Points&Potential'!$B$7:$O$943, 14, FALSE)=0, "", VLOOKUP(B65, 'Points&Potential'!$B$7:$O$943, 14, FALSE)) | V65: =IF(ISERROR(VLOOKUP(B65, Paste!$T$3:$T$1045, 1, FALSE)), "", VLOOKUP(B65, Paste!$T$3:$U$1144, 2, FALSE))
A66: 60 | B66: Dylan Larkin | C66: =VLOOKUP(B66, Paste!$AG$3:$AH$2083, 2, FALSE) -> 29.9 | D66: =VLOOKUP($B66, Paste!$A$3:$H$933, 6, FALSE) -> C | E66: =IFERROR(VLOOKUP($B66, Paste!$J$3:$L$933, 3, FALSE), "") -> 75 | F66: =IFERROR(VLOOKUP($B66, Paste!$J$3:$L$933, 2, FALSE), "") -> 85 | G66: =VLOOKUP($B66, Paste!$A$3:$H$933, 8, FALSE) -> DET | H66: =VLOOKUP($B66, Paste!$A$3:$H$933, 2, FALSE) -> 77 | I66: =VLOOKUP($B66, Paste!$A$3:$H$933, 3, FALSE) -> 33.239642 | J66: =K66-I66 -> 38.324892 | K66: =VLOOKUP($B66, Paste!$A$3:$H$933, 4, FALSE) -> 71.564535 | L66: =IF(ISBLANK(VLOOKUP(B66, 'SOG&PlusMinus'!$B$7:$E$912, 3, FALSE)), "", VLOOKUP(B66,'SOG&PlusMinus'!$B$7:$E$912, 3, FALSE)) -> C | M66: =IF(ISBLANK(VLOOKUP(B66, 'SOG&PlusMinus'!$B$7:$E$912, 4, FALSE)), "", VLOOKUP(B66, 'SOG&PlusMinus'!$B$7:$E$912, 4, FALSE)) -> 1 | N66: =VLOOKUP($B66, Paste!$A$3:$H$933, 5, FALSE) -> 43.65625 | O66: =IF(ISERROR(VLOOKUP(B66, Paste!$AB$3:$AE$2349, 3, FALSE)), "", VLOOKUP(B66, Paste!$AB$3:$AE$2349, 3, FALSE)) -> 46 | P66: =IF(ISERROR(VLOOKUP(B66, Paste!$AB$3:$AC$2343, 2, FALSE)), "", VLOOKUP(B66, Paste!$AB$3:$AC$2343, 2, FALSE)) -> 35 | Q66: =IF(ISERROR(VLOOKUP(B66, Paste!$AB$3:$AE$2349, 4, FALSE)), "", VLOOKUP(B66, Paste!$AB$3:$AE$2349, 4, FALSE)) -> 239 | R66: =IF(ISERROR(VLOOKUP(B66, Paste!$N$3:$N$250, 1, FALSE)), "", VLOOKUP(B66, Paste!$N$3:$O$250, 2, FALSE)) | S66: =VLOOKUP($B66, Paste!$W$3:$Z$10064, IF($H$4="Cap Hit",3, IF($H$4="AAV", 4, 2)), FALSE) -> 8.7 | T66: =IF(ISERROR(VLOOKUP(B66, Paste!$Q$3:$Q$245, 1, FALSE)), "", VLOOKUP(B66, Paste!$Q$3:$R$245, 2, FALSE)) | U66: =IF(VLOOKUP(B66, 'Points&Potential'!$B$7:$O$943, 14, FALSE)=0, "", VLOOKUP(B66, 'Points&Potential'!$B$7:$O$943, 14, FALSE)) | V66: =IF(ISERROR(VLOOKUP(B66, Paste!$T$3:$T$1045, 1, FALSE)), "", VLOOKUP(B66, Paste!$T$3:$U$1144, 2, FALSE))
A67: 61 | B67: Dylan Strome | C67: =VLOOKUP(B67, Paste!$AG$3:$AH$2083, 2, FALSE) -> 29.3 | D67: =VLOOKUP($B67, Paste!$A$3:$H$933, 6, FALSE) -> C | E67: =IFERROR(VLOOKUP($B67, Paste!$J$3:$L$933, 3, FALSE), "") -> 67 | F67: =IFERROR(VLOOKUP($B67, Paste!$J$3:$L$933, 2, FALSE), "") -> 85 | G67: =VLOOKUP($B67, Paste!$A$3:$H$933, 8, FALSE) -> WAS | H67: =VLOOKUP($B67, Paste!$A$3:$H$933, 2, FALSE) -> 83.333333 | I67: =VLOOKUP($B67, Paste!$A$3:$H$933, 3, FALSE) -> 24.956373 | J67: =K67-I67 -> 46.086908 | K67: =VLOOKUP($B67, Paste!$A$3:$H$933, 4, FALSE) -> 71.043281 | L67: =IF(ISBLANK(VLOOKUP(B67, 'SOG&PlusMinus'!$B$7:$E$912, 3, FALSE)), "", VLOOKUP(B67,'SOG&PlusMinus'!$B$7:$E$912, 3, FALSE)) -> C | M67: =IF(ISBLANK(VLOOKUP(B67, 'SOG&PlusMinus'!$B$7:$E$912, 4, FALSE)), "", VLOOKUP(B67, 'SOG&PlusMinus'!$B$7:$E$912, 4, FALSE)) -> 1 | N67: =VLOOKUP($B67, Paste!$A$3:$H$933, 5, FALSE) -> 34.836066 | O67: =IF(ISERROR(VLOOKUP(B67, Paste!$AB$3:$AE$2349, 3, FALSE)), "", VLOOKUP(B67, Paste!$AB$3:$AE$2349, 3, FALSE)) -> 15 | P67: =IF(ISERROR(VLOOKUP(B67, Paste!$AB$3:$AC$2343, 2, FALSE)), "", VLOOKUP(B67, Paste!$AB$3:$AC$2343, 2, FALSE)) -> 55 | Q67: =IF(ISERROR(VLOOKUP(B67, Paste!$AB$3:$AE$2349, 4, FALSE)), "", VLOOKUP(B67, Paste!$AB$3:$AE$2349, 4, FALSE)) -> 150 | R67: =IF(ISERROR(VLOOKUP(B67, Paste!$N$3:$N$250, 1, FALSE)), "", VLOOKUP(B67, Paste!$N$3:$O$250, 2, FALSE)) | S67: =VLOOKUP($B67, Paste!$W$3:$Z$10064, IF($H$4="Cap Hit",3, IF($H$4="AAV", 4, 2)), FALSE) -> 5 | T67: =IF(ISERROR(VLOOKUP(B67, Paste!$Q$3:$Q$245, 1, FALSE)), "", VLOOKUP(B67, Paste!$Q$3:$R$245, 2, FALSE)) | U67: =IF(VLOOKUP(B67, 'Points&Potential'!$B$7:$O$943, 14, FALSE)=0, "", VLOOKUP(B67, 'Points&Potential'!$B$7:$O$943, 14, FALSE)) | V67: =IF(ISERROR(VLOOKUP(B67, Paste!$T$3:$T$1045, 1, FALSE)), "", VLOOKUP(B67, Paste!$T$3:$U$1144, 2, FALSE))
A68: 62 | B68: Nick Schmaltz | C68: =VLOOKUP(B68, Paste!$AG$3:$AH$2083, 2, FALSE) -> 30.3 | D68: =VLOOKUP($B68, Paste!$A$3:$H$933, 6, FALSE) -> RW | E68: =IFERROR(VLOOKUP($B68, Paste!$J$3:$L$933, 3, FALSE), "") -> 70 | F68: =IFERROR(VLOOKUP($B68, Paste!$J$3:$L$933, 2, FALSE), "") -> 75 | G68: =VLOOKUP($B68, Paste!$A$3:$H$933, 8, FALSE) -> UTA | H68: =VLOOKUP($B68, Paste!$A$3:$H$933, 2, FALSE) -> 83 | I68: =VLOOKUP($B68, Paste!$A$3:$H$933, 3, FALSE) -> 30.71 | J68: =K68-I68 -> 40.250642 | K68: =VLOOKUP($B68, Paste!$A$3:$H$933, 4, FALSE) -> 70.960642 | L68: =IF(ISBLANK(VLOOKUP(B68, 'SOG&PlusMinus'!$B$7:$E$912, 3, FALSE)), "", VLOOKUP(B68,'SOG&PlusMinus'!$B$7:$E$912, 3, FALSE)) -> A | M68: =IF(ISBLANK(VLOOKUP(B68, 'SOG&PlusMinus'!$B$7:$E$912, 4, FALSE)), "", VLOOKUP(B68, 'SOG&PlusMinus'!$B$7:$E$912, 4, FALSE)) -> 1 | N68: =VLOOKUP($B68, Paste!$A$3:$H$933, 5, FALSE) -> 17.761317 | O68: =IF(ISERROR(VLOOKUP(B68, Paste!$AB$3:$AE$2349, 3, FALSE)), "", VLOOKUP(B68, Paste!$AB$3:$AE$2349, 3, FALSE)) -> 18 | P68: =IF(ISERROR(VLOOKUP(B68, Paste!$AB$3:$AC$2343, 2, FALSE)), "", VLOOKUP(B68, Paste!$AB$3:$AC$2343, 2, FALSE)) -> 46 | Q68: =IF(ISERROR(VLOOKUP(B68, Paste!$AB$3:$AE$2349, 4, FALSE)), "", VLOOKUP(B68, Paste!$AB$3:$AE$2349, 4, FALSE)) -> 191 | R68: =IF(ISERROR(VLOOKUP(B68, Paste!$N$3:$N$250, 1, FALSE)), "", VLOOKUP(B68, Paste!$N$3:$O$250, 2, FALSE)) | S68: =VLOOKUP($B68, Paste!$W$3:$Z$10064, IF($H$4="Cap Hit",3, IF($H$4="AAV", 4, 2)), FALSE) -> 8 | T68: =IF(ISERROR(VLOOKUP(B68, Paste!$Q$3:$Q$245, 1, FALSE)), "", VLOOKUP(B68, Paste!$Q$3:$R$245, 2, FALSE)) | U68: =IF(VLOOKUP(B68, 'Points&Potential'!$B$7:$O$943, 14, FALSE)=0, "", VLOOKUP(B68, 'Points&Potential'!$B$7:$O$943, 14, FALSE)) | V68: =IF(ISERROR(VLOOKUP(B68, Paste!$T$3:$T$1045, 1, FALSE)), "", VLOOKUP(B68, Paste!$T$3:$U$1144, 2, FALSE))
